Workbook

Sheet 생산일지 (4)
AU1: SMC 생산일지
DG2: 46210
A4: 1. 기본사항
A6: 품명 | J6: SMC 물탱크용 | AF6: 온도 | BA6: ℃ | BE6: 습도 | BY6: % | CD6: 날씨 | CW6: 생산 Batch | DJ6: 1 | DU6: Batch
A7: Lot | J7: HYVINA-WTG-260707-1~ | AF7: 생산시간 | BE7: 비가동 내역 | BP7: 생산준비 및 청소 | CD7: 작업인원 | CL7: 6 | CT7: 명 | CW7: 생산 중량 | DJ7: =CH52 -> 0 | DU7: Kg
A9: 2. 원재료 투입량 | BP9: 3. 점도 확인
A11: No | E11: 품목 | P11: 규격 | Z11: 사용량 (Kg) | AL11: 총 원료 사용량 (Kg) | AY11: 실 원료 사용량 (Kg) | BP11: No. | BV11: 초기점도 (PS/℃) | CD11: 증점거동(PS/℃)
CD12: 5분 | CM12: 10분 | CW12: 15분 | DG12: 20분 | DQ12: 25분
A13: 1 | E13: 불포화수지 | P13: SC-637S | Z13: 350 | AL13: =Z13*$DJ$6 -> 350 | AY13: 1730 | BP13: 1
A14: 2 | E14: 저수축제 | P14: PS40 | Z14: 112.5 | AL14: =Z14*$DJ$6 -> 112.5 | AY14: 560 | BP14: 2
A15: 3 | E15: 희석제 | P15: SM | Z15: 37.5 | AL15: =Z15*$DJ$6 -> 37.5 | AY15: 285 | BP15: 3
A16: 3-2 | E16: 희석제 | P16: SM | Z16: 20 | AL16: =Z16*$DJ$6 -> 20 | AY16: 25 | BP16: 4 | EB16: =4.6-30% -> 4.3
A17: 4 | E17: 첨가제 | P17: K972 | Z17: 5 | AL17: =Z17*$DJ$6 -> 5 | AY17: 25 | BP17: 5
A18: 5 | E18: 첨가제 | P18: K996 | Z18: 6.6 | AL18: =Z18*$DJ$6 -> 6.6 | AY18: 25 | BP18: 6
A19: 6 | E19: 중합금지제 | P19: CBA109N | Z19: 8.5 | AL19: =Z19*$DJ$6 -> 8.5 | AY19: 42.5
A20: 7 | E20: 경화제 | P20: TBPB | Z20: 6 | AL20: =Z20*$DJ$6 -> 6 | AY20: 30 | BP20: 4. 토출량 확인 | EB20: =2.8*5 -> 14 | EC20: =5*1.5 -> 7.5
A21: 8 | E21: 초기 증점조절제 | P21: CBA308S | Z21: 7.5 | AL21: =Z21*$DJ$6 -> 7.5 | AY21: 25
A22: 9 | E22: 저수축제 | P22: FHP | Z22: 25 | AL22: =Z22*$DJ$6 -> 25 | AY22: 125 | BP22: 품목 | CF22: 토출 비 | CT22: 토출량 | DH22: 실토출량 | EB22: =46*0.33 -> 15.18
A23: 10 | E23: 이형제 | P23: HI-FLOW | Z23: 20 | AL23: =Z23*$DJ$6 -> 20 | AY23: 125 | BP23: =ROUND('설정값 계산'!C43,1) -> 33.9 | EB23: =46-EB22 -> 30.82
A24: 11 | E24: 충진제 | P24: CaCO3 | Z24: 825 | AL24: =Z24*$DJ$6 -> 825 | AY24: 4238 | BP24: 컴파운드(Kg/min) | CF24: =SUM(Z13:AK24)/SUM(Z13:AK27) -> 0.97667398 | CT24: =BP23*CF24 -> 33.109248 | EA24: =BP23*CF24 -> 33.109248 | EC24: =5*2.5 -> 12.5
AL25: =Z25*$DJ$6 -> 0 | EA25: =BP23*CF26 -> 0.32560373
A26: 12 | E26: 증점제 | P26: MGO-813 | Z26: 14 | AL26: =Z26*$DJ$6 -> 14 | AY26: 52 | BP26: 증점제(g/min) | CF26: =Z26/SUM(Z13:AK27) -> 0.0096048299 | CT26: =BP23*CF26*1000 -> 325.60373 | EA26: =BP23*CF28 -> 0.46514819
A27: 13 | E27: 조색제 | P27: GRAY (9098) | Z27: 20 | AL27: =Z27*$DJ$6 -> 20 | AY27: 88 | EB27: =4.6*10 -> 46
A28: 14 | E28: 유리섬유 | P28: 4800TEX | Z28: 0.33 | AE28: =SUM(Z13:AJ27)/(1-Z28)*Z28 -> 717.92239 | AL28: =AE28*$DJ$6 -> 717.92239 | AY28: =Q59 | BP28: 조색제(g/min) | CF28: =Z27/SUM(Z13:AK27) -> 0.013721186 | CT28: =BP23*CF28*1000 -> 465.14819
A29: TTL | Z29: =SUM(Z13:AK27)+AE28 -> 2175.5224 | AL29: =SUM(AL13:AX28) -> 2175.5224 | AY29: =SUM(AY13:BL28) -> 7375.5
A31: 4. SMC 생산 확인
A33: No | E33: 온도 (℃) | K33: 습도 (%) | R33: 제품 폭 (mm) | AA33: 생산 속도 (m/min) | AJ33: D/B 1,2 (mm) | AT33: CUTTER 1/2 RPM | BD33: 단중 (Kg/m2) | BN33: 함침 정도 (%) | BX33: 총 중량 (Kg) | CH33: 실 중량 (Kg) | CR33: 말기점도 (PS/℃) | DD33: 비고
A35: 1 | R35: 1100 | AA35: 10 | AJ35: 1.5/1.5 | AT35: 59/59 | BD35: 4.6(5.06)
A36: 2
A37: 3
A38: 4
A39: 5
A40: 6
A41: 7
A42: 8
A43: 9
A44: 10
A45: 11
A46: 12
A47: 13
...

Sheet 일일 생산일지(신규)
B1: SMC 일일 생산일지
B2: 파란 글씨(노란 칸) = 직접 입력 | 초록 글씨 = 자동 연동(설정값 계산 시트) | 검정 글씨 = 자동 계산
B4: 1. 기본사항
B5: 품명 | C5: SMC 물탱크용 | F5: 제품 Lot | K5: 생산 Batch | L5: 2 | M5: 목표 생산중량 | O5: 0
B6: 온도℃ | C6: 0 | D6: 습도% | E6: 0 | F6: 날씨 | K6: 작업인원 | L6: 6 | M6: 생산시간
B8: 2. 원재료 투입량 (Lot 포함) | J8: 3. 점도 확인 (회차별)
B9: No | C9: 품목 | D9: 규격 | E9: Lot No. | F9: 사용량 (Kg) | G9: 총사용량 (Kg) | H9: 실사용량 (Kg) | J9: 회차 | K9: 초기점도 (PS/℃) | L9: 5분 | M9: 10분 | N9: 15분 | O9: 20분 | P9: 25분 | Q9: 말기점도 (PS/℃)
B10: 1 | C10: 불포화수지 | D10: SC-637S | F10: 350 | G10: =F10*$L$5 -> 700 | H10: 0 | J10: 1 | K10: 0 | L10: 0 | M10: 0 | N10: 0 | O10: 0 | P10: 0 | Q10: 0
B11: 2 | C11: 저수축제 | D11: PS40 | F11: 112.5 | G11: =F11*$L$5 -> 225 | H11: 0 | J11: 2 | K11: 0 | L11: 0 | M11: 0 | N11: 0 | O11: 0 | P11: 0 | Q11: 0
B12: 3 | C12: 희석제 | D12: SM | F12: 37.5 | G12: =F12*$L$5 -> 75 | H12: 0 | J12: 3 | K12: 0 | L12: 0 | M12: 0 | N12: 0 | O12: 0 | P12: 0 | Q12: 0
B13: 3-2 | C13: 희석제 | D13: SM | F13: 20 | G13: =F13*$L$5 -> 40 | H13: 0 | J13: 4 | K13: 0 | L13: 0 | M13: 0 | N13: 0 | O13: 0 | P13: 0 | Q13: 0
B14: 4 | C14: K972 | D14: K972 | F14: 5 | G14: =F14*$L$5 -> 10 | H14: 0 | J14: 5 | K14: 0 | L14: 0 | M14: 0 | N14: 0 | O14: 0 | P14: 0 | Q14: 0
B15: 5 | C15: K996 | D15: K996 | F15: 6.6 | G15: =F15*$L$5 -> 13.2 | H15: 0 | J15: 6 | K15: 0 | L15: 0 | M15: 0 | N15: 0 | O15: 0 | P15: 0 | Q15: 0
B16: 6 | C16: 중합금지제 | D16: CBA109N | F16: 8.5 | G16: =F16*$L$5 -> 17 | H16: 0 | J16: 7 | K16: 0 | L16: 0 | M16: 0 | N16: 0 | O16: 0 | P16: 0 | Q16: 0
B17: 7 | C17: 경화제 | D17: TBPB | F17: 6 | G17: =F17*$L$5 -> 12 | H17: 0 | J17: 8 | K17: 0 | L17: 0 | M17: 0 | N17: 0 | O17: 0 | P17: 0 | Q17: 0
B18: 8 | C18: 초기증점조절제 | D18: CBA308S | F18: 7.5 | G18: =F18*$L$5 -> 15 | H18: 0 | J18: 9 | K18: 0 | L18: 0 | M18: 0 | N18: 0 | O18: 0 | P18: 0 | Q18: 0
B19: 9 | C19: 저수축제 | D19: FHP | F19: 25 | G19: =F19*$L$5 -> 50 | H19: 0 | J19: 10 | K19: 0 | L19: 0 | M19: 0 | N19: 0 | O19: 0 | P19: 0 | Q19: 0
B20: 10 | C20: 이형제 | D20: HI-FLOW | F20: 20 | G20: =F20*$L$5 -> 40 | H20: 0 | J20: 11 | K20: 0 | L20: 0 | M20: 0 | N20: 0 | O20: 0 | P20: 0 | Q20: 0
B21: 11 | C21: 충진제 | D21: CaCO3 | F21: 825 | G21: =F21*$L$5 -> 1650 | H21: 0 | J21: 12 | K21: 0 | L21: 0 | M21: 0 | N21: 0 | O21: 0 | P21: 0 | Q21: 0
B22: 12 | C22: 증점제 | D22: MGO-813 | F22: 14 | G22: =F22*$L$5 -> 28 | J22: 13 | K22: 0 | L22: 0 | M22: 0 | N22: 0 | O22: 0 | P22: 0 | Q22: 0
B23: 13 | C23: 조색제 | D23: GRAY(9098) | F23: 20 | G23: =F23*$L$5 -> 40 | J23: 14 | K23: 0 | L23: 0 | M23: 0 | N23: 0 | O23: 0 | P23: 0 | Q23: 0
B24: 14 | C24: 유리섬유 | D24: 4800TEX | F24: 717.92 | G24: =F24*$L$5 -> 1435.84
B25: TTL | F25: =SUM(F10:F24) -> 2175.52 | G25: =SUM(G10:G24) -> 4351.04 | H25: =SUM(H10:H24) -> 0
B27: 4. 유리섬유 함량 체크 | J27: ="5. 토출량 확인 " -> 5. 토출량 확인 | N27: 33.9
B28: 유리섬유 Lot | J28: 항목 | L28: 목표(자동) | M28: 실측 | N28: 단위
B29: 롤 사용량(Kg) | J29: 컴파운드(페이스트) | L29: =IFERROR(N27*(1-(F22+F23)/SUM($F$10:$F$23)),"") -> 33.109248 | M29: 0 | N29: Kg/min
B30: 전체사용량(Kg) | D30: =SUM(D29:H29) -> 0 | F30: 함량(%) | G30: =IFERROR(D30/(SUM(H10:H24)),"") | J30: 증점제 | L30: =IFERROR(N27*F22/SUM($F$10:$F$23)*1000,"") -> 325.60373 | M30: 0 | N30: g/min
J31: 조색제 | L31: =IFERROR(N27*F23/SUM($F$10:$F$23)*1000,"") -> 465.14819 | M31: 0 | N31: g/min
J32: ※ 비율 = 증점제·조색제 사용량 ÷ 전체 사용량
B34: 6. 생산 확인 (Doctor Box 높이 · 유리섬유 컷터 RPM · 단중 · 생산중량)
B35: ↓ 권장값 (설정값 계산 시트 연동) | E35: =IFERROR('설정값 계산'!C52,"") -> 1.6551218 | F35: =IFERROR('설정값 계산'!C52,"") -> 1.6551218 | G35: =IFERROR('설정값 계산'!G60,"") -> 59.443863 | H35: =IFERROR('설정값 계산'!G61,"") -> 59.443863 | J35: 4.6
B36: NO | C36: 제품 폭 (mm) | D36: 생산 속도 (m/min) | E36: D/B 1 (mm) | F36: D/B 2 (mm) | G36: 컷터1 RPM | H36: 컷터2 RPM | J36: 단중 (Kg/㎡) | K36: 함침정도 (%) | L36: 총중량 (Kg) | M36: 실중량 (Kg) | N36: 비고
B37: 1 | C37: 0 | D37: 0 | E37: 0 | F37: 0 | G37: 0 | H37: 0 | J37: 0 | K37: 0 | L37: 0 | M37: 0
B38: 2 | C38: 0 | D38: 0 | E38: 0 | F38: 0 | G38: 0 | H38: 0 | J38: 0 | K38: 0 | L38: 0 | M38: 0
B39: 3 | C39: 0 | D39: 0 | E39: 0 | F39: 0 | G39: 0 | H39: 0 | J39: 0 | K39: 0 | L39: 0 | M39: 0
B40: 4 | C40: 0 | D40: 0 | E40: 0 | F40: 0 | G40: 0 | H40: 0 | J40: 0 | K40: 0 | L40: 0 | M40: 0
B41: 5 | C41: 0 | D41: 0 | E41: 0 | F41: 0 | G41: 0 | H41: 0 | J41: 0 | K41: 0 | L41: 0 | M41: 0
B42: 6 | C42: 0 | D42: 0 | E42: 0 | F42: 0 | G42: 0 | H42: 0 | J42: 0 | K42: 0 | L42: 0 | M42: 0
B43: 7 | C43: 0 | D43: 0 | E43: 0 | F43: 0 | G43: 0 | H43: 0 | J43: 0 | K43: 0 | L43: 0 | M43: 0
B44: 8 | C44: 0 | D44: 0 | E44: 0 | F44: 0 | G44: 0 | H44: 0 | J44: 0 | K44: 0 | L44: 0 | M44: 0
...

Sheet 설정값 계산
B1: SMC 설정값 계산 (Doctor Blade 토출량 · 갭 · 컷터 RPM)
B2: 파란 글씨(노란 칸) = 직접 입력 | 초록 글씨 = 작업일지에서 자동으로 가져옴 | 검정 글씨 = 자동 계산. 원본: SMC Doctor Blade Flow Rate Calculator
B4: 핵심 결과 (토출 총량은 작업일지 4번 토출량 확인 표에 자동 반영됩니다)
B5: 페이스트 토출 총량 | C5: 컷터 1 / 2 RPM | E5: Doctor Box 갭 (각각)
B6: =C43 -> 33.902 | C6: =IF(ISNUMBER(G60),TEXT(G60,"0.0"),"OFF")&" / "&IF(ISNUMBER(G61),TEXT(G61,"0.0"),"OFF") -> 59.4 / 59.4 | E6: =C52 -> 1.6551218
B8: 1. 작업일지에서 가져온 값 (작업일지 4번 표의 첫 줄)
B9: 라인 속도 | C9: ='생산일지 (4)'!AA35 -> 10 | D9: m/min | E9: 작업일지 「생산 속도」 칸
B10: 제품 폭 | C10: ='생산일지 (4)'!R35 -> 1100 | D10: mm | E10: 작업일지 「제품 폭」 칸
B11: 유리섬유 함량 | C11: ='생산일지 (4)'!Z28 -> 0.33 | E11: 작업일지 원재료 표 유리섬유 행의 비율
B13: 2. 설정 입력
B14: 목표 단중 | C14: 4.6 | D14: Kg/m² | E14: 작업일지 「단중」과 같은 값 (예: 4.6)
B15: 블레이드 두께 (L) | C15: 6 | D15: mm
B16: 페이스트 점도 (η) | C16: 10000 | D16: cps
B17: 페이스트 높이 (H) | C17: 50 | D17: mm
B19: 3. 비중 (작업일지 배합표 사용량 기준 · 비중 값은 배합.xlsx 원가계산서 실측치)
B20: 품목 | C20: 규격 | D20: 사용량 (Kg) | E20: 비중 (g/cm³) | F20: 부피 (L) | G20: 비고
B21: ='생산일지 (4)'!E13 -> 불포화수지 | C21: ='생산일지 (4)'!P13 -> SC-637S | D21: ='생산일지 (4)'!Z13 -> 350 | E21: 1.1 | F21: =IFERROR(D21/E21,0) -> 318.18182 | G21: 배합.xlsx 불포화수지 비중
B22: ='생산일지 (4)'!E14 -> 저수축제 | C22: ='생산일지 (4)'!P14 -> PS40 | D22: ='생산일지 (4)'!Z14 -> 112.5 | E22: 1 | F22: =IFERROR(D22/E22,0) -> 112.5 | G22: 배합.xlsx 저수축제(PS40) 비중
B23: ='생산일지 (4)'!E15 -> 희석제 | C23: ='생산일지 (4)'!P15 -> SM | D23: ='생산일지 (4)'!Z15 -> 37.5 | E23: 0.91 | F23: =IFERROR(D23/E23,0) -> 41.208791 | G23: 배합.xlsx 희석제(SM) 비중
B24: ='생산일지 (4)'!E16 -> 희석제 | C24: ='생산일지 (4)'!P16 -> SM | D24: ='생산일지 (4)'!Z16 -> 20 | E24: 0.91 | F24: =IFERROR(D24/E24,0) -> 21.978022 | G24: 배합.xlsx 희석제(SM) 비중
B25: ='생산일지 (4)'!E17 -> 첨가제 | C25: ='생산일지 (4)'!P17 -> K972 | D25: ='생산일지 (4)'!Z17 -> 5 | E25: 1.02 | F25: =IFERROR(D25/E25,0) -> 4.9019608 | G25: 배합.xlsx K972 비중
B26: ='생산일지 (4)'!E18 -> 첨가제 | C26: ='생산일지 (4)'!P18 -> K996 | D26: ='생산일지 (4)'!Z18 -> 6.6 | E26: 1.04 | F26: =IFERROR(D26/E26,0) -> 6.3461538 | G26: 배합.xlsx K996 비중
B27: ='생산일지 (4)'!E19 -> 중합금지제 | C27: ='생산일지 (4)'!P19 -> CBA109N | D27: ='생산일지 (4)'!Z19 -> 8.5 | E27: 0.91 | F27: =IFERROR(D27/E27,0) -> 9.3406593 | G27: 배합.xlsx CBA109N 비중
B28: ='생산일지 (4)'!E20 -> 경화제 | C28: ='생산일지 (4)'!P20 -> TBPB | D28: ='생산일지 (4)'!Z20 -> 6 | E28: 1.04 | F28: =IFERROR(D28/E28,0) -> 5.7692308 | G28: 배합.xlsx T-BPB 비중
B29: ='생산일지 (4)'!E21 -> 초기 증점조절제 | C29: ='생산일지 (4)'!P21 -> CBA308S | D29: ='생산일지 (4)'!Z21 -> 7.5 | E29: 0.98 | F29: =IFERROR(D29/E29,0) -> 7.6530612 | G29: 배합.xlsx상 CBA-307F(초기증점조절제 동일 역할) 비중
B30: ='생산일지 (4)'!E22 -> 저수축제 | C30: ='생산일지 (4)'!P22 -> FHP | D30: ='생산일지 (4)'!Z22 -> 25 | E30: 0.96 | F30: =IFERROR(D30/E30,0) -> 26.041667 | G30: 배합.xlsx FHP05040 비중
B31: ='생산일지 (4)'!E23 -> 이형제 | C31: ='생산일지 (4)'!P23 -> HI-FLOW | D31: ='생산일지 (4)'!Z23 -> 20 | E31: 1.1 | F31: =IFERROR(D31/E31,0) -> 18.181818 | G31: 배합.xlsx상 ZN-ST(이형제 동일 역할) 비중
B32: ='생산일지 (4)'!E24 -> 충진제 | C32: ='생산일지 (4)'!P24 -> CaCO3 | D32: ='생산일지 (4)'!Z24 -> 825 | E32: 2.7 | F32: =IFERROR(D32/E32,0) -> 305.55556 | G32: 배합.xlsx CaCO3 비중
B33: ='생산일지 (4)'!E26 -> 증점제 | C33: ='생산일지 (4)'!P26 -> MGO-813 | D33: ='생산일지 (4)'!Z26 -> 14 | E33: 1.5 | F33: =IFERROR(D33/E33,0) -> 9.3333333 | G33: 배합.xlsx상 CBU-813(증점제 동일 역할) 비중
B34: ='생산일지 (4)'!E27 -> 조색제 | C34: ='생산일지 (4)'!P27 -> GRAY (9098) | D34: ='생산일지 (4)'!Z27 -> 20 | E34: 2.05 | F34: =IFERROR(D34/E34,0) -> 9.7560976 | G34: 배합.xlsx 조색제 비중
B35: 합계 (유리섬유 제외) | D35: =SUM(D21:D34) -> 1457.6 | F35: =SUM(F21:F34) -> 896.74817
B36: 페이스트 비중 (유리섬유 제외) | C36: =IFERROR(D35/F35,0) -> 1.6254285 | D36: g/cm³ | E36: 배합.xlsx 「컴파운드 비중」과 같은 개념
B37: ='생산일지 (4)'!E28 -> 유리섬유 | C37: ='생산일지 (4)'!P28 -> 4800TEX | D37: ='생산일지 (4)'!AE28 -> 717.92239 | E37: 2.54 | F37: =IFERROR(D37/E37,0) -> 282.64661 | G37: 배합.xlsx 유리섬유 비중
B38: SMC 전체 비중 (유리섬유 포함) | C38: =IFERROR((D35+D37)/(F35+F37),0) -> 1.8446091 | D38: g/cm³ | E38: 배합.xlsx 「전체 비중」과 같은 개념 (참고: 배합.xlsx 물탱크 배합 자체 계산값 1.8473)
B39: 4. Doctor Blade 토출량 · 갭 계산
B40: SMC 시트 중량 (길이 1m당) | C40: =C14*C10 -> 5060 | D40: g/m | E40: 단중 × 폭
B41: 페이스트 중량 (길이 1m당) | C41: =C40*(1-C11) -> 3390.2 | D41: g/m | E41: 유리섬유 제외
B42: 유리섬유 중량 (길이 1m당) | C42: =C40*C11 -> 1669.8 | D42: g/m
B43: ★ 페이스트 토출 총량 | C43: =C41*C9/1000 -> 33.902 | D43: Kg/min | E43: → 작업일지 토출 총량으로 연결
B44: 페이스트 체적 유량 (Q) | C44: =IFERROR(C43/C36,0) -> 20.85727 | D44: L/min
...
