Workbook
Name CV: #REF!
Name CV: #REF!
Name CV: #REF!
Name d: #REF!
Name d: #REF!
Name d: #REF!
Name sad: #REF!
Name sad: #REF!
Name sad: #REF!
Name SADA: #REF!
Name SADA: #REF!
Name SADA: #REF!
Name sdfc: #REF!
Name sdfc: #REF!
Name sdfc: #REF!
Name ㄱ쇼: #REF!
Name ㄱ쇼: #REF!
Name ㄱ쇼: #REF!
Name ㄴㄴㄴㄴㄴ: #REF!
Name ㄴㄴㄴㄴㄴ: #REF!
Name ㄴㄴㄴㄴㄴ: #REF!
Name 품명: #REF!
Name 품명: #REF!
Name 품명: #REF!

Sheet 생산일지 (4)
AU1: SMC 생산일지
DG2: 46210
A4: 1. 기본사항
A6: 품명 | J6: SMC 물탱크용 | AF6: 온도 | BA6: ℃ | BE6: 습도 | BY6: % | CD6: 날씨 | CW6: 생산 Batch | DJ6: 1 | DU6: Batch
A7: Lot | J7: HYVINA-WTG-260707-1~ | AF7: 생산시간 | BE7: 비가동 내역 | BP7: 생산준비 및 청소 | CD7: 작업인원 | CL7: 6 | CT7: 명 | CW7: 생산 중량 | DJ7: =CH52 -> 0 | DU7: Kg
A9: 2. 원재료 투입량 | BP9: 3. 점도 확인
A11: No | E11: 품목 | P11: 규격 | Z11: 사용량 (Kg) | AL11: 총 원료 사용량 (Kg) | AY11: 실 원료 사용량 (Kg) | BP11: No. | BV11: 초기점도 (PS/℃) | CD11: 증점거동(PS/℃)
CD12: 5분 | CM12: 10분 | CW12: 15분 | DG12: 20분 | DQ12: 25분
A13: 1 | E13: 불포화수지 | P13: SC-637S | Z13: 350 | AL13: =Z13*$DJ$6 -> 350 | AY13: 1730 | BP13: 1
A14: 2 | E14: 저수축제 | P14: PS40 | Z14: 112.5 | AL14: =Z14*$DJ$6 -> 112.5 | AY14: 560 | BP14: 2
A15: 3 | E15: 희석제 | P15: SM | Z15: 37.5 | AL15: =Z15*$DJ$6 -> 37.5 | AY15: 285 | BP15: 3
A16: 3-2 | E16: 희석제 | P16: SM | Z16: 20 | AL16: =Z16*$DJ$6 -> 20 | AY16: 25 | BP16: 4 | EB16: =4.6-30% -> 4.3
A17: 4 | E17: 첨가제 | P17: K972 | Z17: 5 | AL17: =Z17*$DJ$6 -> 5 | AY17: 25 | BP17: 5
A18: 5 | E18: 첨가제 | P18: K996 | Z18: 6.6 | AL18: =Z18*$DJ$6 -> 6.6 | AY18: 25 | BP18: 6
A19: 6 | E19: 중합금지제 | P19: CBA109N | Z19: 8.5 | AL19: =Z19*$DJ$6 -> 8.5 | AY19: 42.5
A20: 7 | E20: 경화제 | P20: TBPB | Z20: 6 | AL20: =Z20*$DJ$6 -> 6 | AY20: 30 | BP20: 4. 토출량 확인 | EB20: =2.8*5 -> 14 | EC20: =5*1.5 -> 7.5
A21: 8 | E21: 초기 증점조절제 | P21: CBA308S | Z21: 7.5 | AL21: =Z21*$DJ$6 -> 7.5 | AY21: 25
A22: 9 | E22: 저수축제 | P22: FHP | Z22: 25 | AL22: =Z22*$DJ$6 -> 25 | AY22: 125 | BP22: 품목 | CF22: 토출 비 | CT22: 토출량 | DH22: 실토출량 | EB22: =46*0.33 -> 15.18
A23: 10 | E23: 이형제 | P23: HI-FLOW | Z23: 20 | AL23: =Z23*$DJ$6 -> 20 | AY23: 125 | BP23: 33 | EB23: =46-EB22 -> 30.82
A24: 11 | E24: 충진제 | P24: CaCO3 | Z24: 825 | AL24: =Z24*$DJ$6 -> 825 | AY24: 4238 | BP24: 컴파운드(Kg/min) | CF24: =SUM(Z13:AK24)/SUM(Z13:AK27) -> 0.97667398 | CT24: =BP23*CF24 -> 32.230241 | EA24: =BP23*CF24 -> 32.230241 | EC24: =5*2.5 -> 12.5
AL25: =Z25*$DJ$6 -> 0 | EA25: =BP23*CF26 -> 0.31695939
A26: 12 | E26: 증점제 | P26: MGO-813 | Z26: 14 | AL26: =Z26*$DJ$6 -> 14 | AY26: 52 | BP26: 증점제(g/min) | CF26: =Z26/SUM(Z13:AK27) -> 0.0096048299 | CT26: =BP23*CF26*1000 -> 316.95939 | EA26: =BP23*CF28 -> 0.45279912
A27: 13 | E27: 조색제 | P27: GRAY (9098) | Z27: 20 | AL27: =Z27*$DJ$6 -> 20 | AY27: 88 | EB27: =4.6*10 -> 46
A28: 14 | E28: 유리섬유 | P28: 4800TEX | Z28: 0.33 | AE28: =SUM(Z13:AJ27)/(1-Z28)*Z28 -> 717.92239 | AL28: =AE28*$DJ$6 -> 717.92239 | AY28: =Q59 -> #DIV/0! | BP28: 조색제(g/min) | CF28: =Z27/SUM(Z13:AK27) -> 0.013721186 | CT28: =BP23*CF28*1000 -> 452.79912
A29: TTL | Z29: =SUM(Z13:AK27)+AE28 -> 2175.5224 | AL29: =SUM(AL13:AX28) -> 2175.5224 | AY29: =SUM(AY13:BL28) -> #DIV/0!
A31: 4. SMC 생산 확인
A33: No | E33: 온도 (℃) | K33: 습도 (%) | R33: 제품 폭 (mm) | AA33: 생산 속도 (m/min) | AJ33: D/B 1,2 (mm) | AT33: CUTTER 1/2 RPM | BD33: 단중 (Kg/m2) | BN33: 함침 정도 (%) | BX33: 총 중량 (Kg) | CH33: 실 중량 (Kg) | CR33: 말기점도 (PS/℃) | DD33: 비고
A35: 1 | R35: 1100 | AA35: 10 | AJ35: 1.5/1.5 | AT35: 59/59 | BD35: 4.6(5.06)
A36: 2
A37: 3
A38: 4
A39: 5
A40: 6
A41: 7
A42: 8
A43: 9
A44: 10
A45: 11
A46: 12
A47: 13
...

Sheet 생산일지 0.5
AU1: SMC 생산일지
DG2: 46186
A4: 1. 기본사항
A6: 품명 | J6: SMC 물탱크용 | AF6: 온도 | BA6: ℃ | BE6: 습도 | BY6: % | CD6: 날씨 | CW6: 생산 Batch | DJ6: 2 | DU6: Batch
A7: Lot | J7: HYVINA-WTG-2606013-1~ | AF7: 생산시간 | AQ7: 13:00~16:00 | BE7: 비가동 내역 | BP7: 생산준비 및 청소 | CD7: 작업인원 | CL7: 6 | CT7: 명 | CW7: 생산 중량 | DJ7: =CH52 -> 0 | DU7: Kg
A9: 2. 원재료 투입량 | BP9: 3. 점도 확인
A11: No | E11: 품목 | P11: 규격 | Z11: 사용량 (Kg) | AL11: 총 원료 사용량 (Kg) | AY11: 실 원료 사용량 (Kg) | BP11: No. | BV11: 초기점도 (PS/℃) | CD11: 증점거동(PS/℃)
CD12: 5분 | CM12: 10분 | CW12: 15분 | DG12: 20분 | DQ12: 25분
A13: 1 | E13: 불포화수지 | P13: SC-637S | Z13: 175 | AL13: =Z13*$DJ$6 -> 350 | AY13: 200.56 | BP13: 1 | EA13: 175
A14: 2 | E14: 저수축제 | P14: PS40 | Z14: 56.25 | AL14: =Z14*$DJ$6 -> 112.5 | AY14: 64.48 | BP14: 2 | EA14: 56.25 | EB14: =1.45*1.5 -> 2.175
A15: 3 | E15: 희석제 | P15: SM | Z15: 18.75 | AL15: =Z15*$DJ$6 -> 37.5 | AY15: 32 | BP15: 3 | EA15: 18.75
A16: 4 | E16: 희석제 | P16: SM | Z16: 10 | AL16: 2.96 | AY16: 25 | BP16: 4 | EA16: 10
A17: 5 | E17: 첨가제 | P17: K972 | Z17: 2.5 | AL17: 2 | AY17: 25 | BP17: 5 | EA17: 2.5
E18: 첨가제 | P18: K996 | Z18: 2.5 | AL18: =Z18*$DJ$6 -> 5 | BP18: 6 | EA18: 2.5
A19: 6 | E19: 중합금지제 | P19: CBA109N | Z19: 4.25 | AL19: 3.1 | AY19: 42.5 | EA19: 4.25
A20: 7 | E20: 경화제 | P20: TBPB | Z20: 3 | AL20: =Z20*$DJ$6 -> 6 | AY20: 30 | BP20: 4. 토출량 확인 | EA20: 3
A21: 8 | E21: 초기 증점조절제 | P21: CBA308S | Z21: 3.25 | AL21: =Z21*$DJ$6 -> 6.5 | AY21: 25 | EA21: 3.25
A22: 9 | E22: 저수축제 | P22: FHP | Z22: 12.5 | AL22: 11.97 | AY22: 125 | BP22: 품목 | CF22: 토출 비 | CT22: 토출량(Kg/min) | DH22: 실토출량 | EA22: 12.5
A23: 10 | E23: 이형제 | P23: HI-FLOW | Z23: 12.5 | AL23: 11.97 | AY23: 125 | BP23: 34 | DH23: 토출량 | DN23: 시작 | DT23: 종료 | EA23: 12.5
A24: 11 | E24: 충진제 | P24: CaCO3 | Z24: 425 | AL24: =Z24*$DJ$6 -> 850 | AY24: 4238 | BP24: 컴파운드(Kg/min) | CF24: =SUM(Z13:AK24)/SUM(Z13:AK27) -> 0.97974342 | CT24: =BP23*CF24 -> 33.311276 | EA24: 412.5
AL25: =Z25*$DJ$6 -> 0 | EA25: 0
A26: 12 | E26: 증점제 | P26: MGO-813 | Z26: 5 | AL26: =Z26*$DJ$6 -> 10 | AY26: 52 | BP26: 증점제(g/min) | CF26: =Z26/SUM(Z13:AK27) -> 0.0067521945 | CT26: =BP23*CF26*1000 -> 229.57461 | EA26: 5
A27: 13 | E27: 조색제 | P27: GRAY (9098) | Z27: 10 | AL27: =Z27*$DJ$6 -> 20 | AY27: 88 | EA27: 10
A28: 14 | E28: 유리섬유 | P28: 4800TEX | Z28: 0.31 | AE28: =SUM(Z13:AJ27)/(1-Z28)*Z28 -> 332.68841 | AL28: =AE28*$DJ$6 -> 665.37681 | AY28: =Q60 -> #DIV/0! | BP28: 조색제(g/min) | CF28: =Z27/SUM(Z13:AK27) -> 0.013504389 | CT28: =BP23*CF28*1000 -> 459.14922 | EA28: 0.155
A29: TTL | Z29: =SUM(Z13:AK27)+AE28 -> 1073.1884 | AL29: =SUM(AL13:AX28) -> 2094.8768 | AY29: =SUM(AY13:BL28) -> #DIV/0!
A31: 4. SMC 생산 확인
A33: No | E33: 온도 (℃) | K33: 습도 (%) | R33: 제품 폭 (mm) | AA33: 생산 속도 (m/min) | AJ33: D/B 1,2 (mm) | AT33: CUTTER 1/2 RPM | BD33: 단중 (Kg/m2) | BN33: 함침 정도 (%) | BX33: 총 중량 (Kg) | CH33: 실 중량 (Kg) | CR33: 말기점도 (PS/℃) | DD33: 비고
A35: 1
A36: 2
A37: 3
A38: 4
A39: 5
A40: 6
A41: 7
A42: 8
A43: 9
A44: 10
A45: 11
A46: 12
... A51: 17
...

Sheet 배합지시서(40%) (2)
A3: 배합 생산 지시서
X5: 46179
A6: 1. 기본 사항
A7: 품명 | C7: SMC 물탱크 | G7: 온도(℃)/습도(%) | R7: 배합작업자 | T7: 김길동 | W7: 생산 Batch | Y7: 1 | Z7: Batch | AB7: 2
A8: Lot No | C8: HYVINA-WTG | G8: 배합시간 | T8: 박말순 | W8: 생산량 | Y8: =Y7*F30 -> 2110.8696 | Z8: KG
A10: 2. 배합 순서 및 확인 사항
A11: 순번 | B11: 품목 | D11: 규격 | F11: 투입량 (Kg) | H11: 실제 투입량 확인(Kg) | W11: 교반기 속도 (RPM) | Y11: 비고 | AE11: =150-112.5 -> 37.5
H12: 0.5 | L12: 2 | O12: 3 | Q12: 4 | S12: 5 | U12: 6
A14: 1 | B14: 불포화수지 | D14: SC-637S | F14: 350 | H14: =F14/2 -> 175 | S14: 4.3 | W14: 400 | AD14: =F14+F15 -> 462.5
A15: 2 | B15: 저수축제 | D15: PS40 | F15: 112.5 | H15: =F15/2 -> 56.25 | S15: 1.35 | W15: 400 | AD15: =F14/AD14 -> 0.75675676 | AE15: =F15/AD14 -> 0.24324324
A16: 3 | B16: 희석제 | D16: SM | F16: 37.5 | H16: =F16/2 -> 18.75 | S16: 0.45 | W16: 400 | Y16: 점도 이상시 5~10kg 투입
A17: 4 | B17: 첨가제 | D17: K972 | F17: 5 | H17: =F17/2 -> 2.5 | S17: 0.061 | W17: 400
A18: 5 | B18: 첨가제 | D18: K996 | F18: 5 | H18: =F18/2 -> 2.5 | S18: 0.061 | W18: 400
A20: 6 | B20: 중합금지제 | D20: CBA109N | F20: 8.5 | H20: =F20/2 -> 4.25 | S20: 0.104 | W20: 400
A21: 7 | B21: 경화제 | D21: TBPB | F21: 6 | H21: =F21/2 -> 3 | S21: 0.07 | W21: 400
A22: 8 | B22: 초기 증점조절제 | D22: CBA308S | F22: 5 | H22: =F22/2 -> 2.5 | S22: 0.061 | W22: 400
A23: 9 | B23: 저수축제 | D23: FHP | F23: 25 | H23: =F23/2 -> 12.5 | S23: 0.31 | W23: 600
A24: 10 | B24: 이형제 | D24: HI-FLOW | F24: 25 | H24: =F24/2 -> 12.5 | S24: 0.31 | W24: 600
A25: 11 | B25: 충진제 | D25: S-3000 | F25: 850 | H25: =F25/2 -> 425 | S25: 10.4 | W25: 750~950
H26: =F26/2 -> 0 | W26: 150
A27: 12 | B27: 증점제 | D27: MGO-813 | F27: 11 | H27: =F27/2 -> 5.5 | S27: 0.13 | W27: =F27/SUM(F14:F25) -> 0.0076949983
A28: 13 | B28: 조색제 | D28: GRAY (9098) | F28: 16 | H28: =F28/2 -> 8 | S28: 0.2 | W28: =F28/SUM(F14:F25) -> 0.011192725
A29: 14 | B29: 유리섬유 | D29: 4800TEX | F29: 0.31
A30: TTL | F30: =SUM(F14:G28)+W30 -> 2110.8696 | W30: =SUM(F14:G28)/(1-F29)*F29 -> 654.36957
A32: 3. Compound 관리
A33: No | B33: 초기점도 (PS/℃) | D33: 증점거동(PS/℃) | T33: 말기점도(PS/℃) | Y33: 비고
D34: 5분 | F34: 10분 | H34: 15분 | N34: 20분 | Q34: 25분
A35: 1
A36: 2
A37: 3
A38: 4
A39: 5
A40: 6
A42: 4. 기타 특이 사항
K43: 41.3
F44: =SUM(H14:K26)/SUM(H14:K28) -> 0.98146241 | K44: =K43*F44 -> 40.534398 | Q44: kg/min
D45: 증점제 | F45: =SUM(H27:J27)/SUM(H14:K28) -> 0.0075523515 | K45: =K43*F45*1000 -> 311.91212 | Q45: g/min
D46: 조색제 | F46: =SUM(H28:J28)/SUM(H14:K28) -> 0.010985239 | K46: =K43*F46*1000 -> 453.69035 | Q46: .g/min

Sheet 배합지시서 (30%)
A3: 배합 생산 지시서
Q5: 46147
A6: 1. 기본 사항
A7: 품명 | C7: SMC 물탱크 | G7: 온도(℃)/습도(%) | L7: 배합작업자 | P7: 생산 Batch | R7: 2 | S7: Batch | U7: 2
A8: Lot No | C8: HYVINA WTG | E8: 260505-01~ | G8: 배합시간 | P8: 생산량 | R8: =R7*F29 -> 2168.6921 | S8: KG
A10: 2. 배합 순서 및 확인 사항
A11: 순번 | B11: 품목 | D11: 규격 | F11: 투입량 (Kg) | H11: 총 투입량 (Kg) | J11: 확인 | P11: 교반기 속도 (RPM) | R11: 비고
J12: 1 | K12: 2 | L12: 3 | M12: 4 | N12: 5 | O12: 6
A13: 1 | B13: 불포화수지 | F13: =ROUND('물탱크 배합'!K5,-1) -> 180 | H13: =F13*$R$7 -> 360 | P13: 400
A14: 2 | B14: 저수축제 | D14: PS30 | F14: =ROUND('물탱크 배합'!K6,-1) -> 80 | H14: =F14*$R$7 -> 160 | P14: 400
H15: =F15*$R$7 -> 0
A16: 3 | B16: 첨가제 | D16: K972 | F16: =ROUND('물탱크 배합'!K8,1) -> 2.5 | H16: =F16*$R$7 -> 5 | P16: 400
A17: 4 | B17: 첨가제 | D17: K996 | F17: =ROUND('물탱크 배합'!K9,1) -> 2.5 | H17: =F17*$R$7 -> 5 | P17: 400
A18: 5 | B18: 희석제 | D18: SM | F18: =ROUND('물탱크 배합'!K10,1) -> 18.8 | H18: =F18*$R$7 -> 37.6 | P18: 400
A19: 6 | B19: 중합금지제 | D19: CBA109N | F19: =ROUND('물탱크 배합'!K11,1) -> 3.8 | H19: =F19*$R$7 -> 7.6 | P19: 400
A20: 7 | B20: 경화제 | D20: TBPB | F20: =ROUND('물탱크 배합'!K12,1) -> 3 | H20: =F20*$R$7 -> 6 | P20: 400
A21: 8 | B21: 초기 증점조절제 | D21: CBA308S | F21: =ROUND('물탱크 배합'!K14,1) -> 3.8 | H21: =F21*$R$7 -> 7.6 | P21: 600
A22: 9 | B22: 저수축제 | D22: FHP | F22: =ROUND('물탱크 배합'!K15,1) -> 12.5 | H22: =F22*$R$7 -> 25 | P22: 600
A23: 10 | B23: 이형제 | D23: HI-FLOW | F23: =ROUND('물탱크 배합'!K16,1) -> 12.5 | H23: =F23*$R$7 -> 25 | P23: 600
A24: 11 | B24: 충진제 | D24: S-3000 | F24: =ROUND('물탱크 배합'!K18,-1) -> 430 | H24: =F24*$R$7 -> 860 | P24: 750~950 | R24: 45℃이하 관리
P25: 150 | R25: *탈포
A26: 12 | B26: 증점제 | D26: MGO-813 | F26: ='물탱크 배합'!K19 -> 3.7567084 | H26: =F26*R7 -> 7.5134168 | P26: =F26/SUM(F13:G24) -> 0.0050129549
A27: 13 | B27: 조색제 | D27: GRAY (9098) | F27: ='물탱크 배합'!K20 -> 10.017889 | H27: =F27*R7 -> 20.035778 | P27: =F27/SUM(F13:G24) -> 0.01336788
A28: 14 | B28: 유리섬유 | D28: 4800TEX | F28: 0.3
A29: TTL | F29: =SUM(F13:G27)+P29 -> 1084.346 | P29: =SUM(F13:G25)/(1-F28)*F28 -> 321.17143
A31: 3. 점도 관리
A32: 순번 | B32: 초기점도 (PS/℃) | D32: 증점거동(PS/℃) | N32: 말기점도(PS/℃) | R32: 비고
D33: 5분 | F33: 10분 | H33: 15분 | J33: 20분 | L33: 25분
A34: 1 | B34: 123/35 | D34: 123/33 | F34: 200/33 | H34: 450/33 | J34: 500/33 | L34: 650/30 | N34: 4.5*105 | R34: 이상없음
A35: 2
A36: 3
A37: 4
A38: 5
A39: 6
A41: 4. 기타 특이 사항

Sheet 물탱크 배합
A2: 1)원재료비
A3: 품목 | B3: 단가적용 | C3: 비중 | F3: 물탱크 | M3: 물탱크2 | U3: YSACC1 | AC3: YSACC2
F4: Batch | G4: 백분율 | H4: 1톤 배합량 | I4: 원재료비 (원/kg) | J4: phr phf | K4: 1120 | N4: Batch | O4: 백분율 | P4: 1톤 배합량 | Q4: 원재료비 (원/kg) | R4: phr phf | S4: 609 | V4: Batch | W4: 백분율 | X4: 1톤 배합량 | Y4: 원재료비 (원/kg) | Z4: phr phf | AA4: 2500 | AD4: Batch | AE4: 백분율 | AF4: 1톤 배합량 | AG4: 원재료비 (원/kg) | AH4: phr phf | AI4: 2300 | AL4: Batch | AM4: 백분율 | AN4: 1톤 배합량 | AO4: 원재료비 (원/kg) | AP4: phr phf | AQ4: 3185
A5: 불포화수지 | B5: 2700 | C5: 1.1 | E5: =F5/C5 -> 63.636364 | F5: 70 | G5: =F5/F23 -> 0.15652952 | H5: =IF(F5="","",F5/F$23*(1000/H$24)) -> 156.52952 | I5: =IF(F5="","",B5*H5/1000) -> 422.6297 | J5: =IF(F5="","",F5/SUM(F$5:F$6)*100) -> 70 | K5: =IF(H5="","",H5*(K$23/H$23)) -> 175.31306 | M5: =N5/C5 -> 63.636364 | N5: 70 | O5: =N5/N23 -> 0.16466714 | P5: =IF(N5="","",N5/N$23*(1000/P$24)) -> 164.66714 | Q5: =IF(N5="","",B5*P5/1000) -> 444.60127 | R5: =IF(N5="","",N5/SUM(N$5:N$6)*100) -> 70 | S5: =IF(P5="","",P5*(S$23/P$23)) -> 100.28229 | U5: =V5/C5 -> 59.090909 | V5: 65 | W5: =V5/V23 -> 0.14853748 | X5: =IF(V5="","",V5/V$23*(1000/X$24)) -> 151.56885 | Y5: =IF(V5="","",B5*X5/1000) -> 409.23591 | Z5: =IF(V5="","",V5/SUM(V$5:V$6)*100) -> 65 | AA5: =IF(X5="","",X5*(AA$23/X$23)) -> 378.92214 | AC5: =AD5/K5 -> 0.37646939 | AD5: 66 | AE5: =AD5/AD23 -> 0.15052341 | AF5: =IF(AD5="","",AD5/AD$23*(1000/AF$24)) -> 153.59532 | AG5: =IF(AD5="","",B5*AF5/1000) -> 414.70736 | AH5: =IF(AD5="","",AD5/SUM(AD$5:AD$6)*100) -> 76.744186 | AI5: =IF(AF5="","",AF5*(AI$23/AF$23)) -> 353.26923 | AK5: =AL5/S5 -> 4.8862069 | AL5: 490 | AM5: =AL5/AL23 -> 0.44922806 | AN5: =IF(AL5="","",AL5/AL$23*(1000/AN$24)) -> 449.22806 | AO5: =IF(AL5="","",J5*AN5/1000) -> 31.445964 | AP5: =IF(AL5="","",AL5/SUM(AL$5:AL$6)*100) -> 70 | AQ5: =IF(AN5="","",AN5*(AQ$23/AN$23)) -> 1430.7914 | AR5: 490
A6: 저수축제 | B6: 2500 | C6: 1 | E6: =F6/C6 -> 30 | F6: 30 | G6: =F6/F23 -> 0.067084079 | H6: =IF(F6="","",F6/F$23*(1000/H$24)) -> 67.084079 | I6: =IF(F6="","",B6*H6/1000) -> 167.7102 | J6: =IF(F6="","",F6/SUM(F$5:F$6)*100) -> 30 | K6: =IF(H6="","",H6*(K$23/H$23)) -> 75.134168 | M6: =N6/C6 -> 30 | N6: 30 | O6: =N6/N23 -> 0.07057163 | P6: =IF(N6="","",N6/N$23*(1000/P$24)) -> 70.57163 | Q6: =IF(N6="","",B6*P6/1000) -> 176.42908 | R6: =IF(N6="","",N6/SUM(N$5:N$6)*100) -> 30 | S6: =IF(P6="","",P6*(S$23/P$23)) -> 42.978123 | U6: =V6/C6 -> 35 | V6: 35 | W6: =V6/V23 -> 0.079981718 | X6: =IF(V6="","",V6/V$23*(1000/X$24)) -> 81.613998 | Y6: =IF(V6="","",B6*X6/1000) -> 204.035 | Z6: =IF(V6="","",V6/SUM(V$5:V$6)*100) -> 35 | AA6: =IF(X6="","",X6*(AA$23/X$23)) -> 204.035 | AC6: =AD6/K6 -> 0.26619048 | AD6: 20 | AE6: =AD6/AD23 -> 0.045613155 | AF6: =IF(AD6="","",AD6/AD$23*(1000/AF$24)) -> 46.544036 | AG6: =IF(AD6="","",B6*AF6/1000) -> 116.36009 | AH6: =IF(AD6="","",AD6/SUM(AD$5:AD$6)*100) -> 23.255814 | AI6: =IF(AF6="","",AF6*(AI$23/AF$23)) -> 107.05128 | AK6: =AL6/S6 -> 4.8862069 | AL6: 210 | AM6: =AL6/AL23 -> 0.19252631 | AN6: =IF(AL6="","",AL6/AL$23*(1000/AN$24)) -> 192.52631 | AO6: =IF(AL6="","",J6*AN6/1000) -> 5.7757894 | AP6: =IF(AL6="","",AL6/SUM(AL$5:AL$6)*100) -> 30 | AQ6: =IF(AN6="","",AN6*(AQ$23/AN$23)) -> 613.1963 | AR6: 210
P7: =IF(N7="","",N7/N$23*(1000/P$24)) | Q7: =IF(N7="","",B7*P7/1000) | X7: =IF(V7="","",V7/V$23*(1000/X$24)) | Y7: =IF(V7="","",B7*X7/1000) | AF7: =IF(AD7="","",AD7/AD$23*(1000/AF$24)) | AG7: =IF(AD7="","",B7*AF7/1000) | AN7: =IF(AL7="","",AL7/AL$23*(1000/AN$24)) | AO7: =IF(AL7="","",J7*AN7/1000)
A8: K972(분리방지제) | B8: 22500 | C8: 1.02 | E8: =F8/C8 -> 0.98039216 | F8: 1 | G8: =F8/F23 -> 0.002236136 | H8: =IF(F8="","",F8/F$23*(1000/H$24)) -> 2.236136 | I8: =IF(F8="","",B8*H8/1000) -> 50.313059 | J8: =IF(F8="","",F8/SUM(F$5:F$6)*100) -> 1 | K8: =IF(H8="","",H8*(K$23/H$23)) -> 2.5044723 | N8: 1 | O8: =N8/N23 -> 0.0023523877 | P8: =IF(N8="","",N8/N$23*(1000/P$24)) -> 2.3523877 | Q8: =IF(N8="","",B8*P8/1000) -> 52.928723 | R8: =IF(N8="","",N8/SUM(N$5:N$6)*100) -> 1 | S8: =IF(P8="","",P8*(S$23/P$23)) -> 1.4326041 | U8: =V8/C8 -> 1.1764706 | V8: 1.2 | W8: =V8/V23 -> 0.0027422303 | X8: =IF(V8="","",V8/V$23*(1000/X$24)) -> 2.7981942 | Y8: =IF(V8="","",B8*X8/1000) -> 62.95937 | Z8: =IF(V8="","",V8/SUM(V$5:V$6)*100) -> 1.2 | AA8: =IF(X8="","",X8*(AA$23/X$23)) -> 6.9954856 | AC8: =AD8/K8 -> 0.15971429 | AD8: 0.4 | AE8: =AD8/AD23 -> 0.0009122631 | AF8: =IF(AD8="","",AD8/AD$23*(1000/AF$24)) -> 0.93088071 | AG8: =IF(AD8="","",B8*AF8/1000) -> 20.944816 | AH8: =IF(AD8="","",AD8/SUM(AD$5:AD$6)*100) -> 0.46511628 | AI8: =IF(AF8="","",AF8*(AI$23/AF$23)) -> 2.1410256 | AK8: =AL8/S8 -> 2.4431034 | AL8: 3.5 | AM8: =AL8/AL23 -> 0.0032087719 | AN8: =IF(AL8="","",AL8/AL$23*(1000/AN$24)) -> 3.2087719 | AO8: =IF(AL8="","",J8*AN8/1000) -> 0.0032087719 | AP8: =IF(AL8="","",AL8/SUM(AL$5:AL$6)*100) -> 0.5 | AQ8: =IF(AN8="","",AN8*(AQ$23/AN$23)) -> 10.219938
A9: K996(분산제) | B9: 15300 | C9: 1.04 | E9: =F9/C9 -> 0.96153846 | F9: 1 | G9: =F9/F23 -> 0.002236136 | H9: =IF(F9="","",F9/F$23*(1000/H$24)) -> 2.236136 | I9: =IF(F9="","",B9*H9/1000) -> 34.21288 | J9: =IF(F9="","",F9/F$18*100) -> 0.58823529 | K9: =IF(H9="","",H9*(K$23/H$23)) -> 2.5044723 | N9: 1 | O9: =N9/N23 -> 0.0023523877 | P9: =IF(N9="","",N9/N$23*(1000/P$24)) -> 2.3523877 | Q9: =IF(N9="","",B9*P9/1000) -> 35.991531 | R9: =IF(N9="","",N9/SUM(N$18)*100) -> 0.58823529 | S9: =IF(P9="","",P9*(S$23/P$23)) -> 1.4326041 | U9: =V9/C9 -> 0 | W9: =V9/V23 -> 0 | X9: =IF(V9="","",V9/V$23*(1000/X$24)) | Y9: =IF(V9="","",B9*X9/1000) | Z9: =IF(V9="","",V9/SUM(V$5:V$6)*100) | AA9: =IF(X9="","",X9*(AA$23/X$23)) | AC9: =AD9/K9 -> 0 | AE9: =AD9/AD23 -> 0 | AF9: =IF(AD9="","",AD9/AD$23*(1000/AF$24)) | AG9: =IF(AD9="","",B9*AF9/1000) | AH9: =IF(AD9="","",AD9/SUM(AD$5:AD$6)*100) | AI9: =IF(AF9="","",AF9*(AI$23/AF$23)) | AK9: =AL9/S9 -> 7.3293103 | AL9: 10.5 | AM9: =AL9/AL23 -> 0.0096263156 | AN9: =IF(AL9="","",AL9/AL$23*(1000/AN$24)) -> 9.6263156 | AO9: =IF(AL9="","",J9*AN9/1000) -> 0.0056625386 | AP9: =IF(AL9="","",AL9/SUM(AL$5:AL$6)*100) -> 1.5 | AQ9: =IF(AN9="","",AN9*(AQ$23/AN$23)) -> 30.659815
A10: SM(희석제) | B10: 3600 | C10: 0.91 | E10: =F10/C10 -> 8.2417582 | F10: 7.5 | G10: =F10/F23 -> 0.01677102 | H10: =IF(F10="","",F10/F$23*(1000/H$24)) -> 16.77102 | I10: =IF(F10="","",B10*H10/1000) -> 60.375671 | J10: =IF(F10="","",F10/SUM(F$5:F$6)*100) -> 7.5 | K10: =IF(H10="","",H10*(K$23/H$23)) -> 18.783542 | M10: =N10/C10 -> 8.2417582 | N10: 7.5 | O10: =N10/N23 -> 0.017642908 | P10: =IF(N10="","",N10/N$23*(1000/P$24)) -> 17.642908 | Q10: =IF(N10="","",B10*P10/1000) -> 63.514467 | R10: =IF(N10="","",N10/SUM(N$5:N$6)*100) -> 7.5 | S10: =IF(P10="","",P10*(S$23/P$23)) -> 10.744531 | U10: =V10/C10 -> 7.6923077 | V10: 7 | W10: =V10/V23 -> 0.015996344 | X10: =IF(V10="","",V10/V$23*(1000/X$24)) -> 16.3228 | Y10: =IF(V10="","",B10*X10/1000) -> 58.762079 | Z10: =IF(V10="","",V10/SUM(V$5:V$6)*100) -> 7 | AA10: =IF(X10="","",X10*(AA$23/X$23)) -> 40.806999 | AC10: =AD10/K10 -> 0.80496 | AD10: 15.12 | AE10: =AD10/AD23 -> 0.034483545 | AF10: =IF(AD10="","",AD10/AD$23*(1000/AF$24)) -> 35.187291 | AG10: =IF(AD10="","",B10*AF10/1000) -> 126.67425 | AH10: =IF(AD10="","",AD10/SUM(AD$5:AD$6)*100) -> 17.581395 | AI10: =IF(AF10="","",AF10*(AI$23/AF$23)) -> 80.930769 | AK10: =AL10/S10 -> 0.72595074 | AL10: 7.8 | AM10: =AL10/AL23 -> 0.0071509773 | AN10: =IF(AL10="","",AL10/AL$23*(1000/AN$24)) -> 7.1509773 | AO10: =IF(AL10="","",J10*AN10/1000) -> 0.05363233 | AP10: =IF(AL10="","",AL10/SUM(AL$5:AL$6)*100) -> 1.1142857 | AQ10: =IF(AN10="","",AN10*(AQ$23/AN$23)) -> 22.775863
A11: CBA109N(중합방지제) | B11: 4100 | C11: 0.91 | E11: =F11/C11 -> 1.6483516 | F11: 1.5 | G11: =F11/F23 -> 0.0033542039 | H11: =IF(F11="","",F11/F$23*(1000/H$24)) -> 3.3542039 | I11: =IF(F11="","",B11*H11/1000) -> 13.752236 | J11: =IF(F11="","",F11/SUM(F$5:F$6)*100) -> 1.5 | K11: =IF(H11="","",H11*(K$23/H$23)) -> 3.7567084 | M11: =N11/C11 -> 1.8681319 | N11: 1.7 | O11: =N11/N23 -> 0.003999059 | P11: =IF(N11="","",N11/N$23*(1000/P$24)) -> 3.999059 | Q11: =IF(N11="","",B11*P11/1000) -> 16.396142 | R11: =IF(N11="","",N11/SUM(N$5:N$6)*100) -> 1.7 | S11: =IF(P11="","",P11*(S$23/P$23)) -> 2.435427 | U11: =V11/C11 -> 0.43956044 | V11: 0.4 | W11: =V11/V23 -> 0.00091407678 | X11: =IF(V11="","",V11/V$23*(1000/X$24)) -> 0.93273141 | Y11: =IF(V11="","",B11*X11/1000) -> 3.8241988 | Z11: =IF(V11="","",V11/SUM(V$5:V$6)*100) -> 0.4 | AA11: =IF(X11="","",X11*(AA$23/X$23)) -> 2.3318285 | AC11: =AD11/K11 -> 0.34604762 | AD11: 1.3 | AE11: =AD11/AD23 -> 0.0029648551 | AF11: =IF(AD11="","",AD11/AD$23*(1000/AF$24)) -> 3.0253623 | AG11: =IF(AD11="","",B11*AF11/1000) -> 12.403985 | AH11: =IF(AD11="","",AD11/SUM(AD$5:AD$6)*100) -> 1.5116279 | AI11: =IF(AF11="","",AF11*(AI$23/AF$23)) -> 6.9583333 | AK11: =AL11/S11 -> 0.69802956 | AL11: 1.7 | AM11: =AL11/AL23 -> 0.0015585463 | AN11: =IF(AL11="","",AL11/AL$23*(1000/AN$24)) -> 1.5585463 | AO11: =IF(AL11="","",J11*AN11/1000) -> 0.0023378195 | AP11: =IF(AL11="","",AL11/SUM(AL$5:AL$6)*100) -> 0.24285714 | AQ11: =IF(AN11="","",AN11*(AQ$23/AN$23)) -> 4.9639701
A12: T-BPB(경화제) | B12: 6000 | C12: 1.04 | E12: =F12/C12 -> 1.1538462 | F12: 1.2 | G12: =F12/F23 -> 0.0026833631 | H12: =IF(F12="","",F12/F$23*(1000/H$24)) -> 2.6833631 | I12: =IF(F12="","",B12*H12/1000) -> 16.100179 | J12: =IF(F12="","",F12/SUM(F$5:F$6)*100) -> 1.2 | K12: =IF(H12="","",H12*(K$23/H$23)) -> 3.0053667 | M12: =N12/C12 -> 1.1538462 | N12: 1.2 | O12: =N12/N23 -> 0.0028228652 | P12: =IF(N12="","",N12/N$23*(1000/P$24)) -> 2.8228652 | Q12: =IF(N12="","",B12*P12/1000) -> 16.937191 | R12: =IF(N12="","",N12/SUM(N$5:N$6)*100) -> 1.2 | S12: =IF(P12="","",P12*(S$23/P$23)) -> 1.7191249 | U12: =V12/C12 -> 1.1538462 | V12: 1.2 | W12: =V12/V23 -> 0.0027422303 | X12: =IF(V12="","",V12/V$23*(1000/X$24)) -> 2.7981942 | Y12: =IF(V12="","",B12*X12/1000) -> 16.789165 | Z12: =IF(V12="","",V12/SUM(V$5:V$6)*100) -> 1.2 | AA12: =IF(X12="","",X12*(AA$23/X$23)) -> 6.9954856 | AC12: =AD12/K12 -> 0.3327381 | AD12: 1 | AE12: =AD12/AD23 -> 0.0022806577 | AF12: =IF(AD12="","",AD12/AD$23*(1000/AF$24)) -> 2.3272018 | AG12: =IF(AD12="","",B12*AF12/1000) -> 13.963211 | AH12: =IF(AD12="","",AD12/SUM(AD$5:AD$6)*100) -> 1.1627907 | AI12: =IF(AF12="","",AF12*(AI$23/AF$23)) -> 5.3525641 | AK12: =AL12/S12 -> 0.5816913 | AL12: 1 | AM12: =AL12/AL23 -> 0.00091679196 | AN12: =IF(AL12="","",AL12/AL$23*(1000/AN$24)) -> 0.91679196 | AO12: =IF(AL12="","",J12*AN12/1000) -> 0.0011001504 | AP12: =IF(AL12="","",AL12/SUM(AL$5:AL$6)*100) -> 0.14285714 | AQ12: =IF(AN12="","",AN12*(AQ$23/AN$23)) -> 2.9199824
B13: 8400 | C13: 1 | E13: =F13/C13 -> 0 | G13: =F13/F23 -> 0 | H13: =IF(F13="","",F13/F$23*(1000/H$24)) | I13: =IF(F13="","",B13*H13/1000) | J13: =IF(F13="","",F13/SUM(F$5:F$6)*100) | K13: =IF(H13="","",H13*(K$23/H$23)) | P13: =IF(N13="","",N13/N$23*(1000/P$24)) | Q13: =IF(N13="","",B13*P13/1000) | R13: =IF(N13="","",N13/SUM(N$5:N$6)*100) | S13: =IF(P13="","",P13*(S$23/P$23)) | U13: =V13/C13 -> 0.5 | V13: 0.5 | W13: =V13/V23 -> 0.001142596 | X13: =IF(V13="","",V13/V$23*(1000/X$24)) -> 1.1659143 | Y13: =IF(V13="","",B13*X13/1000) -> 9.7936798 | Z13: =IF(V13="","",V13/SUM(V$5:V$6)*100) -> 0.5 | AA13: =IF(X13="","",X13*(AA$23/X$23)) -> 2.9147857 | AC13: =AD13/C13 -> 0.5 | AD13: 0.5 | AE13: =AD13/AD23 -> 0.0011403289 | AF13: =IF(AD13="","",AD13/AD$23*(1000/AF$24)) -> 1.1636009 | AG13: =IF(AD13="","",B13*AF13/1000) -> 9.7742475 | AH13: =IF(AD13="","",AD13/SUM(AD$5:AD$6)*100) -> 0.58139535 | AI13: =IF(AF13="","",AF13*(AI$23/AF$23)) -> 2.676282
A14: CBA-307F{초기즘점 조절제} | C14: 0.98 | E14: =F14/C14 -> 1.5306122 | F14: 1.5 | G14: =F14/F24 -> 0.005013369 | H14: =IF(F14="","",F14/F$23*(1000/H$24)) -> 3.3542039 | I14: =IF(F14="","",B14*H14/1000) -> 0 | J14: =IF(F14="","",F14/SUM(F$5:F$6)*100) -> 1.5 | K14: =IF(H14="","",H14*(K$23/H$23)) -> 3.7567084 | N14: 1 | P14: =IF(N14="","",N14/N$23*(1000/P$24)) -> 2.3523877 | Q14: =IF(N14="","",B14*P14/1000) -> 0 | R14: =IF(N14="","",N14/SUM(N$5:N$6)*100) -> 1 | S14: =IF(P14="","",P14*(S$23/P$23)) -> 1.4326041 | X14: =IF(V14="","",V14/V$23*(1000/X$24)) | Y14: =IF(V14="","",B14*X14/1000) | Z14: =IF(V14="","",V14/SUM(V$5:V$6)*100) | AA14: =IF(X14="","",X14*(AA$23/X$23)) | AF14: =IF(AD14="","",AD14/AD$23*(1000/AF$24)) | AG14: =IF(AD14="","",B14*AF14/1000) | AH14: =IF(AD14="","",AD14/SUM(AD$5:AD$6)*100) | AI14: =IF(AF14="","",AF14*(AI$23/AF$23)) | AL14: 1.5 | AM14: =AL14/AL24 -> 0.0015645208 | AN14: =IF(AL14="","",AL14/AL$23*(1000/AN$24)) -> 1.3751879 | AO14: =IF(AL14="","",J14*AN14/1000) -> 0.0020627819 | AP14: =IF(AL14="","",AL14/SUM(AL$5:AL$6)*100) -> 0.21428571 | AQ14: =IF(AN14="","",AN14*(AQ$23/AN$23)) -> 4.3799736
A15: FHP05040 (PE 파우더) | B15: 4000 | C15: 0.96 | E15: =F15/C15 -> 5.2083333 | F15: 5 | G15: =F15/F23 -> 0.01118068 | H15: =IF(F15="","",F15/F$23*(1000/H$24)) -> 11.18068 | I15: =IF(F15="","",B15*H15/1000) -> 44.722719 | J15: =IF(F15="","",F15/SUM(F$5:F$6)*100) -> 5 | K15: =IF(H15="","",H15*(K$23/H$23)) -> 12.522361 | M15: =N15/C15 -> 5.2083333 | N15: 5 | O15: =N15/N23 -> 0.011761938 | P15: =IF(N15="","",N15/N$23*(1000/P$24)) -> 11.761938 | Q15: =IF(N15="","",B15*P15/1000) -> 47.047753 | R15: =IF(N15="","",N15/SUM(N$5:N$6)*100) -> 5 | S15: =IF(P15="","",P15*(S$23/P$23)) -> 7.1630205 | U15: =V15/C15 -> 4.1666667 | V15: 4 | W15: =V15/V23 -> 0.0091407678 | X15: =IF(V15="","",V15/V$23*(1000/X$24)) -> 9.3273141 | Y15: =IF(V15="","",B15*X15/1000) -> 37.309256 | Z15: =IF(V15="","",V15/SUM(V$5:V$6)*100) -> 4 | AA15: =IF(X15="","",X15*(AA$23/X$23)) -> 23.318285 | AC15: =AD15/K15 -> 0.45917857 | AD15: 5.75 | AE15: =AD15/AD23 -> 0.013113782 | AF15: =IF(AD15="","",AD15/AD$23*(1000/AF$24)) -> 13.38141 | AG15: =IF(AD15="","",B15*AF15/1000) -> 53.525641 | AH15: =IF(AD15="","",AD15/SUM(AD$5:AD$6)*100) -> 6.6860465 | AI15: =IF(AF15="","",AF15*(AI$23/AF$23)) -> 30.777244 | AK15: =AL15/S15 -> 0.69802956 | AL15: 5 | AM15: =AL15/AL23 -> 0.0045839598 | AN15: =IF(AL15="","",AL15/AL$23*(1000/AN$24)) -> 4.5839598 | AO15: =IF(AL15="","",J15*AN15/1000) -> 0.022919799 | AP15: =IF(AL15="","",AL15/SUM(AL$5:AL$6)*100) -> 0.71428571 | AQ15: =IF(AN15="","",AN15*(AQ$23/AN$23)) -> 14.599912
A16: ZN-ST(내부이형제) | B16: 3500 | C16: 1.1 | E16: =F16/C16 -> 4.5454545 | F16: 5 | G16: =F16/F23 -> 0.01118068 | H16: =IF(F16="","",F16/F$23*(1000/H$24)) -> 11.18068 | I16: =IF(F16="","",B16*H16/1000) -> 39.132379 | J16: =IF(F16="","",F16/SUM(F$5:F$6)*100) -> 5 | K16: =IF(H16="","",H16*(K$23/H$23)) -> 12.522361 | M16: =N16/C16 -> 4.5454545 | N16: 5 | O16: =N16/N23 -> 0.011761938 | P16: =IF(N16="","",N16/N$23*(1000/P$24)) -> 11.761938 | Q16: =IF(N16="","",B16*P16/1000) -> 41.166784 | R16: =IF(N16="","",N16/SUM(N$5:N$6)*100) -> 5 | S16: =IF(P16="","",P16*(S$23/P$23)) -> 7.1630205 | U16: =V16/C16 -> 3.6363636 | V16: 4 | W16: =V16/V23 -> 0.0091407678 | X16: =IF(V16="","",V16/V$23*(1000/X$24)) -> 9.3273141 | Y16: =IF(V16="","",B16*X16/1000) -> 32.645599 | Z16: =IF(V16="","",V16/SUM(V$5:V$6)*100) -> 4 | AA16: =IF(X16="","",X16*(AA$23/X$23)) -> 23.318285 | AC16: =AD16/K16 -> 0.51907143 | AD16: 6.5 | AE16: =AD16/AD23 -> 0.014824275 | AF16: =IF(AD16="","",AD16/AD$23*(1000/AF$24)) -> 15.126812 | AG16: =IF(AD16="","",B16*AF16/1000) -> 52.94384 | AH16: =IF(AD16="","",AD16/SUM(AD$5:AD$6)*100) -> 7.5581395 | AI16: =IF(AF16="","",AF16*(AI$23/AF$23)) -> 34.791667 | AK16: =AL16/S16 -> 0.90743842 | AL16: 6.5 | AM16: =AL16/AL23 -> 0.0059591478 | AN16: =IF(AL16="","",AL16/AL$23*(1000/AN$24)) -> 5.9591478 | AO16: =IF(AL16="","",J16*AN16/1000) -> 0.029795739 | AP16: =IF(AL16="","",AL16/SUM(AL$5:AL$6)*100) -> 0.92857143 | AQ16: =IF(AN16="","",AN16*(AQ$23/AN$23)) -> 18.979886
P17: =IF(N17="","",N17/N$23*(1000/P$24)) | R17: =IF(N17="","",N17/SUM(N$5:N$6)*100) | X17: =IF(V17="","",V17/V$23*(1000/X$24)) | Y17: =IF(V17="","",B17*X17/1000) | Z17: =IF(V17="","",V17/SUM(V$5:V$6)*100) | AF17: =IF(AD17="","",AD17/AD$23*(1000/AF$24)) | AG17: =IF(AD17="","",B17*AF17/1000) | AH17: =IF(AD17="","",AD17/SUM(AD$5:AD$6)*100) | AN17: =IF(AL17="","",AL17/AL$23*(1000/AN$24)) | AO17: =IF(AL17="","",J17*AN17/1000) | AP17: =IF(AL17="","",AL17/SUM(AL$5:AL$6)*100)
A18: CaCO3(충진제) | B18: 100 | C18: 2.7 | E18: =F18/C18 -> 62.962963 | F18: 170 | G18: =F18/F23 -> 0.38014311 | H18: =IF(F18="","",F18/F$23*(1000/H$24)) -> 380.14311 | I18: =IF(F18="","",B18*H18/1000) -> 38.014311 | J18: =IF(F18="","",F18/SUM(F$5:F$6)*100) -> 170 | K18: =IF(H18="","",H18*(K$23/H$23)) -> 425.76029 | M18: =N18/C18 -> 62.962963 | N18: 170 | O18: =N18/N23 -> 0.3999059 | P18: =IF(N18="","",N18/N$23*(1000/P$24)) -> 399.9059 | Q18: =IF(N18="","",B18*P18/1000) -> 39.99059 | R18: =IF(N18="","",N18/SUM(N$5:N$6)*100) -> 170 | S18: =IF(P18="","",P18*(S$23/P$23)) -> 243.5427 | U18: =V18/C18 -> 68.518519 | V18: 185 | W18: =V18/V23 -> 0.42276051 | X18: =IF(V18="","",V18/V$23*(1000/X$24)) -> 431.38828 | Y18: =IF(V18="","",B18*X18/1000) -> 43.138828 | Z18: =IF(V18="","",V18/SUM(V$5:V$6)*100) -> 185 | AA18: =IF(X18="","",X18*(AA$23/X$23)) -> 1078.4707 | AC18: =AD18/K18 -> 0.43451681 | AD18: 185 | AE18: =AD18/AD23 -> 0.42192168 | AF18: =IF(AD18="","",AD18/AD$23*(1000/AF$24)) -> 430.53233 | AG18: =IF(AD18="","",B18*AF18/1000) -> 43.053233 | AH18: =IF(AD18="","",AD18/SUM(AD$5:AD$6)*100) -> 215.11628 | AI18: =IF(AF18="","",AF18*(AI$23/AF$23)) -> 990.22436 | AK18: =AL18/S18 -> 0.7596204 | AL18: 185 | AM18: =AL18/AL23 -> 0.16960651 | AN18: =IF(AL18="","",AL18/AL$23*(1000/AN$24)) -> 169.60651 | AO18: =IF(AL18="","",J18*AN18/1000) -> 28.833107 | AP18: =IF(AL18="","",AL18/SUM(AL$5:AL$6)*100) -> 26.428571 | AQ18: =IF(AN18="","",AN18*(AQ$23/AN$23)) -> 540.19674
A19: CBU-813(증점제) | B19: 5360 | C19: 1.5 | E19: =F19/C19 -> 1 | F19: 1.5 | G19: =F19/F23 -> 0.0033542039 | H19: =IF(F19="","",F19/F$23*(1000/H$24)) -> 3.3542039 | I19: =IF(F19="","",B19*H19/1000) -> 17.978533 | J19: =IF(F19="","",F19/SUM(F$5:F$6)*100) -> 1.5 | K19: =IF(H19="","",H19*(K$23/H$23)) -> 3.7567084 | M19: =N19/C19 -> 1.4666667 | N19: 2.2 | O19: =N19/N23 -> 0.0051752529 | P19: =IF(N19="","",N19/N$23*(1000/P$24)) -> 5.1752529 | Q19: =IF(N19="","",B19*P19/1000) -> 27.739355 | R19: =IF(N19="","",N19/SUM(N$5:N$6)*100) -> 2.2 | S19: =IF(P19="","",P19*(S$23/P$23)) -> 3.151729 | U19: =V19/C19 -> 0.8 | V19: 1.2 | W19: =V19/V23 -> 0.0027422303 | X19: =IF(V19="","",V19/V$23*(1000/X$24)) -> 2.7981942 | Y19: =IF(V19="","",B19*X19/1000) -> 14.998321 | Z19: =IF(V19="","",V19/SUM(V$5:V$6)*100) -> 1.2 | AA19: =IF(X19="","",X19*(AA$23/X$23)) -> 6.9954856 | AC19: =AD19/K19 -> 1.0115238 | AD19: 3.8 | AE19: =AD19/AD23 -> 0.0086664994 | AF19: =IF(AD19="","",AD19/AD$23*(1000/AF$24)) -> 8.8433668 | AG19: =IF(AD19="","",B19*AF19/1000) -> 47.400446 | AH19: =IF(AD19="","",AD19/SUM(AD$5:AD$6)*100) -> 4.4186047 | AI19: =IF(AF19="","",AF19*(AI$23/AF$23)) -> 20.339744 | AK19: =AL19/S19 -> 5.9522884 | AL19: 18.76 | AM19: =AL19/AL23 -> 0.017199017 | AN19: =IF(AL19="","",AL19/AL$23*(1000/AN$24)) -> 17.199017 | AO19: =IF(AL19="","",J19*AN19/1000) -> 0.025798526 | AP19: =IF(AL19="","",AL19/SUM(AL$5:AL$6)*100) -> 2.68 | AQ19: =IF(AN19="","",AN19*(AQ$23/AN$23)) -> 54.77887
A20: 조색제 | B20: 5149 | C20: 2.05 | E20: =F20/C20 -> 1.9512195 | F20: 4 | G20: =F20/F23 -> 0.0089445438 | H20: =IF(F20="","",F20/F$23*(1000/H$24)) -> 8.9445438 | I20: =IF(F20="","",B20*H20/1000) -> 46.055456 | J20: =IF(F20="","",F20/SUM(F$5:F$6)*100) -> 4 | K20: =IF(H20="","",H20*(K$23/H$23)) -> 10.017889 | M20: =N20/C20 -> 1.7073171 | N20: 3.5 | O20: =N20/N23 -> 0.0082333569 | P20: =IF(N20="","",N20/N$23*(1000/P$24)) -> 8.2333569 | Q20: =IF(N20="","",B20*P20/1000) -> 42.393554 | R20: =IF(N20="","",N20/SUM(N$5:N$6)*100) -> 3.5 | S20: =IF(P20="","",P20*(S$23/P$23)) -> 5.0141143 | U20: =V20/C20 -> 0.53658537 | V20: 1.1 | W20: =V20/V23 -> 0.0025137112 | X20: =IF(V20="","",V20/V$23*(1000/X$24)) -> 2.5650114 | Y20: =IF(V20="","",B20*X20/1000) -> 13.207244 | Z20: =IF(V20="","",V20/SUM(V$5:V$6)*100) -> 1.1 | AA20: =IF(X20="","",X20*(AA$23/X$23)) -> 6.4125284 | AC20: =AD20/K20 -> 0.10980357 | AD20: 1.1 | AE20: =AD20/AD23 -> 0.0025087235 | AF20: =IF(AD20="","",AD20/AD$23*(1000/AF$24)) -> 2.559922 | AG20: =IF(AD20="","",B20*AF20/1000) -> 13.181038 | AH20: =IF(AD20="","",AD20/SUM(AD$5:AD$6)*100) -> 1.2790698 | AI20: =IF(AF20="","",AF20*(AI$23/AF$23)) -> 5.8878205 | AK20: =AL20/S20 -> 3.4901478 | AL20: 17.5 | AM20: =AL20/AL23 -> 0.016043859 | AN20: =IF(AL20="","",AL20/AL$23*(1000/AN$24)) -> 16.043859 | AO20: =IF(AL20="","",J20*AN20/1000) -> 0.064175437 | AP20: =IF(AL20="","",AL20/SUM(AL$5:AL$6)*100) -> 2.5 | AQ20: =IF(AN20="","",AN20*(AQ$23/AN$23)) -> 51.099692
A21: 유리섬유 | B21: 1050 | C21: 2.54 | E21: =F21/C21 -> 58.267717 | F21: 148 | G21: =F21/F23 -> 0.33094812 | H21: =IF(F21="","",F21/F$23*(1000/H$24)) -> 330.94812 | I21: =IF(F21="","",B21*H21/1000) -> 347.49553 | J21: =IF(F21="","",F21/F$23) -> 0.33094812 | K21: =IF(H21="","",H21*(K$23/H$23)) -> 370.6619 | M21: =N21/C21 -> 49.606299 | N21: 126 | O21: =N21/N23 -> 0.29640085 | P21: =IF(N21="","",N21/N$23*(1000/P$24)) -> 296.40085 | Q21: =IF(N21="","",B21*P21/1000) -> 311.22089 | R21: =IF(N21="","",N21/SUM(N$5:N$6)*100) -> 126 | S21: =IF(P21="","",P21*(S$23/P$23)) -> 180.50812 | U21: =V21/C21 -> 51.968504 | V21: 132 | W21: =V21/V23 -> 0.30164534 | X21: =IF(V21="","",V21/V$23*(1000/X$24)) -> 307.80137 | Y21: =IF(V21="","",B21*X21/1000) -> 323.19143 | Z21: =IF(V21="","",V21/SUM(V$5:V$6)*100) -> 132 | AA21: =IF(X21="","",X21*(AA$23/X$23)) -> 769.50341 | AC21: =AD21/K21 -> 0.35611969 | AD21: 132 | AE21: =AD21/AD23 -> 0.30104682 | AF21: =IF(AD21="","",AD21/AD$23*(1000/AF$24)) -> 307.19063 | AG21: =IF(AD21="","",B21*AF21/1000) -> 322.55017 | AH21: =IF(AD21="","",AD21/SUM(AD$5:AD$6)*100) -> 153.48837 | AI21: =IF(AF21="","",AF21*(AI$23/AF$23)) -> 706.53846 | AK21: =AL21/S21 -> 0.73126906 | AL21: 132 | AM21: =AL21/AL23 -> 0.12101654 | AN21: =IF(AL21="","",AL21/AL$23*(1000/AN$24)) -> 121.01654 | AO21: =IF(AL21="","",J21*AN21/1000) -> 0.040050196 | AP21: =IF(AL21="","",AL21/SUM(AL$5:AL$6)*100) -> 18.857143 | AQ21: =IF(AN21="","",AN21*(AQ$23/AN$23)) -> 385.43768
H22: =IF(F22="","",F22/F$23*(1000/H$24)) | I22: =IF(F22="","",#REF!*H22/1000) | J22: =IF(F22="","",F22/F$23) | K22: =IF(H22="","",H22*(K$23/H$23)) | P22: =IF(N22="","",N22/N$23*(1000/P$24)) | Q22: =IF(N22="","",B22*P22/1000) | R22: =IF(N22="","",N22/N$23) | S22: =IF(P22="","",P22*(S$23/P$23)) | X22: =IF(V22="","",V22/V$23*(1000/X$24)) | Y22: =IF(V22="","",J22*X22/1000) | Z22: =IF(V22="","",V22/V$23) | AA22: =IF(X22="","",X22*(AA$23/X$23)) | AF22: =IF(AD22="","",AD22/AD$23*(1000/AF$24)) | AG22: =IF(AD22="","",R22*AF22/1000) | AH22: =IF(AD22="","",AD22/AD$23) | AI22: =IF(AF22="","",AF22*(AI$23/AF$23)) | AN22: =IF(AL22="","",AL22/AL$23*(1000/AN$24)) | AO22: =IF(AL22="","",Z22*AN22/1000) | AP22: =IF(AL22="","",AL22/AL$23) | AQ22: =IF(AN22="","",AN22*(AQ$23/AN$23))
E23: =SUM(E5:E22) -> 242.08855 | F23: =SUM(F5:F22) -> 447.2 | H23: =SUM(H5:H22) -> 1000 | K23: =K4/H24 -> 1120 | M23: =SUM(M5:M22) -> 230.39713 | N23: =SUM(N5:N22) -> 425.1 | P23: =SUM(P5:P22) -> 1000 | S23: =S4/P24 -> 609 | U23: =SUM(U5:U22) -> 234.67973 | V23: =SUM(V5:V22) -> 437.6 | X23: =SUM(X5:X22) -> 1020.4082 | AA23: =AA4/X24 -> 2551.0204 | AC23: =SUM(AC5:AC22) -> 5.6763337 | AD23: =SUM(AD5:AD22) -> 438.47 | AF23: =SUM(AF5:AF22) -> 1020.4082 | AI23: =AI4/AF24 -> 2346.9388 | AK23: =SUM(AK5:AK22) -> 34.089293 | AL23: =SUM(AL5:AL22) -> 1090.76 | AN23: =SUM(AN5:AN22) -> 1000 | AQ23: =AQ4/AN24 -> 3185
E24: =SUM(E5:E20) -> 183.82083 | F24: =SUM(F5:F20) -> 299.2 | H24: 1 | I24: =SUM(I5:I22) -> 1298.4928 | M24: =SUM(M5:M20) -> 180.79083 | N24: =SUM(N5:N20) -> 299.1 | P24: 1 | Q24: =SUM(Q5:Q22) -> 1316.3573 | V24: =SUM(V5:V20) -> 305.6 | X24: 0.98 | Y24: =SUM(Y5:Y22) -> 1229.8901 | AD24: =SUM(AD5:AD20) -> 306.47 | AF24: 0.98 | AG24: =SUM(AG5:AG22) -> 1247.4823 | AL24: =SUM(AL5:AL20) -> 958.76 | AN24: 1 | AO24: =SUM(AO5:AO22) -> 66.305605
E25: 전체 비중 | F25: =F23/E23 -> 1.847258 | M25: 비중 | N25: =N23/M23 -> 1.845075 | U25: 비중 | V25: =V23/U23 -> 1.8646689
E26: 컴파운드 비중 | F26: =F24/E24 -> 1.6276719 | I26: sm 3파트추가 | M26: 컴파운드 비중 | N26: =N24/M24 -> 1.654398
I27: 증점제는 2,2.5파트로 한다.
I28: 초기증점조절제 1.3
A31: 2)부재료비 | E31: 3)노무비 | M31: 4)제조경비 | R31: 5)합계
A32: 품목 | B32: 품목 | C32: 금액 | E32: 1인월작업시간 | F32: 종합시급 | G32: 인원 | H32: 월 생산량(Kg) | I32: 임금계 | J32: 노무비 | M32: 품목 | O32: 월소요량(원) | P32: 금액 | R32: 재료비 | S32: 부재료비 | T32: 노무비 | U32: 제조경비 (감가비 포함) | V32: 소량생산비 (기술비) | W32: 합계
A33: 케리어필름 | B33: CPP필름 | C33: 36.83 | E33: 198 | F33: 4000 | G33: 6 | H33: 200000 | I33: =E33*F33*G33 -> 4752000 | J33: =I33/H33 -> 23.76 | M33: 전기료, 난방비 | O33: 5000000 | P33: =O33/H33 -> 25 | R33: =Q24+C36 -> 1358.1873 | S33: =C36 -> 41.83 | T33: =J33 -> 23.76 | U33: =P38 -> 92 | W33: =R33+T33+U33+V33 -> 1473.9473
A34: UV차단필름 | B34: 알루미늄, 30미크론 | C34: 4 | E34: ◎노무비 참고사항 | M34: 폐자재비 | O34: 1800000 | P34: =O34/H33 -> 9
A35: 테이프 외 | C35: 1 | E35: ①작업인원 : 6명(@198) | H35: ②1인 월 작업시간 : 198시간/월(22일, 1일 9시간) | M35: 환경부담비 | O35: 3300000 | P35: =O35/H33 -> 16.5
A36: 부재료비 계 | C36: =SUM(C33:C35) -> 41.83 | E36: ③환경부담비 : 3.85*85원= 327.25만원/월 | M36: 보수유지비 | O36: 3300000 | P36: =O36/H33 -> 16.5
M37: 시트설비감가비 | O37: 5000000 | P37: =O37/H33 -> 25
M38: 합계 | P38: =SUM(P33:P37) -> 92
Q45: 550
P46: 385 | Q46: =P46/Q45 -> 0.7
P47: 165

Sheet SMC기계 관리가이드
A3: SMC Machine Management & Maintenance Guide | K3: Hướng dẫn Quản lý & Bảo trì Máy SMC
A5: 1. SMC 닥터박스(D/B) 관리 가이드 | K5: 1. Hướng dẫn quản lý Doctor Box (D/B)
A6: 닥터박스는 수지가 직접 담겨 있고 칼날(Blade)을 통해 두께를 조절하는 곳이라, 청소와 관리가 조금이라도 소홀하면 | K6: Doctor Box là bộ phận điều chỉnh độ dày thông qua nhựa và lưỡi gạt (Blade). Nếu việc vệ sinh
A7: 바로 **제품 표면 불량(줄 생김)**이나 두께 불균일로 이어집니다. | K7: và quản lý bị lơ là, bề mặt sản phẩm sẽ bị lỗi ngay lập tức, vì vậy cần phải kiểm tra định kỳ.
A9: ①작업 종료 후 청소 (Daily Cleaning) | K9: ① Vệ sinh sau khi kết thúc công việc (Daily Cleaning)
A10: 수지가 경화(굳음)되기 전에 닦아내는 것이 가장 중요합니다. | K10: Điều quan trọng nhất là phải lau sạch nhựa trước khi nó bị đông cứng.
A12: 수지 배출: 작업이 끝나면 박스 내부의 잔류 수지를 최대한 비워냅니다. | K12: Xả nhựa: Sau khi kết thúc công việc, hãy dọn sạch tối đa lượng nhựa còn sót lại bên trong hộp.
A13: 1차 닦기: 헤라(스크래퍼)를 이용해 벽면에 붙은 수지를 긁어냅니다. 이때 스테인리스 박스라면 플라스틱 및 황동
A14: 헤라를 사용하여 스크래치를 방지하세요. | K14: Lần lau 1: Dùng dao cạo (Hera) để cạo bỏ nhựa dính trên bề mặt. Nếu là hộp inox, hãy
A15: 세척제 활용: 수지 전용 세척제 및 아세톤을 헝겊에 적셔 칼날(Blade)과 박스 내부 구석구석을 닦아냅니다. | K15: sử dụng dao cạo bằng nhựa hoặc đồng để tránh làm trầy xước.
A17: ②칼날 집중 관리 | K17: Sử dụng chất tẩy rửa: Thấm dung dịch tẩy rửa chuyên dụng cho nhựa hoặc axeton
A18: 닥터박스의 핵심인 칼날은 아주 작은 이물질이나 손상에도 예민합니다. | K18: vào vải cotton để lau sạch lưỡi gạt (Blade) và mọi ngóc ngách bên trong hộp.
A20: 칼날 날 끝(Edge) 점검: 청소 시 칼날 끝을 손가락으로 살짝 만져보아(맨손 필수) 거칠거칠한 부분이나 이빨 빠진 곳이 | K20: ② Quản lý tập trung lưỡi gạt
C21: 없는지 확인합니다. | K21: Lưỡi gạt là bộ phận cốt lõi của Doctor Box, rất nhạy cảm với các vật thể lạ hoặc hư
K22: hỏng dù là nhỏ nhất.
A23: ③댐(Dam) 관리
A24: 수지가 옆으로 새는 것을 막아주는 부위입니다. | K24: Kiểm tra cạnh lưỡi (Edge): Khi vệ sinh, hãy dùng ngón tay chạm nhẹ vào cạnh lưỡi
K25: (bắt buộc dùng tay trần) để kiểm tra xem có chỗ nào bị thô ráp hoặc sứt mẻ không.
A26: 측면 댐 청소: 양옆 댐 부위 하단에 컴파운드가 굳거나 유리섬유 가루가 엉겨 붙어 굳는 경우가 많습니다.
B27: 이 부위가 지저분하면 필름이 지나가면서 찢어질 수 있으므로 매일 확인해야 합니다. | K27: ③ Quản lý đệm kín (Dam)
K28: Đây là bộ phận ngăn nhựa rò rỉ ra hai bên.
A29: ④닥터박스 금지 수칙
A30: 철 헤라 사용금지: 칼날 표면에 스크래치를 내면 그 자리에 수지가 더 잘 붙고 시트에 줄이 생깁니다. 반드시 부드러운
B31: 천이나 황동 헤라를 쓰세요.
A32: 무리한 힘 가하지 않기: 닥터박스 세팅이 안 맞는다고 망치로 때리면 정밀한 수평(0.05mm)이 영구적으로 틀어집니다.
C33: 반드시 조절 볼트를 이용하세요.
A34: 잔류 수지 방치 금지: "내일 아침에 닦지 뭐" 하고 퇴근하면 다음 날 D/B를 통째로 갈아야 할 수도 있습니다.
A37: 2. 유리섬유 커팅날( Cutter Blade) 관리 및 교체 가이드
A38: 커팅날이 무뎌지면 유리섬유가 제대로 잘리지 않아 시트 내부에 섬유가 뭉치거나 분산이 불균일해집니다.
A40: 사전 안전 조치
A41: 기계정지 : 설비가 갑자기 구동되지 않도록 반드시 기계를 정지하고 잠금장치를 하세요.
A42: 보호구 착용: 유리섬유 가루는 피부에 박히면 매우 따갑고 눈이나 호흡기에 해롭습니다. 내절단 장갑(방검 장갑), 고글,
A43: 마스크를 반드시 착용하세요.
A45: ①청소 및 관리 가이드 (매 작업 종로 후 필수)
A47: 1단계: 에어건을 이용한 1차 분진 제거
A48: 커팅 유닛 주변과 칼날 사이에 낀 유리섬유 부스러기를 에어건으로 불어냅니다.
A49: 주의: 분진이 비산되므로 반드시 집진기를 가동하거나 환기가 잘 되는 상태에서 작업하세요.
A51: 2단계: 고착된 수지 및 이물질 제거
... A148: 좋습니다.

Sheet SMC 공정별 핵심 가이드
A2: 1. 원재료 배합 공정 (Compounding Standard)
A4: 배합은 화학적 균질성을 결정하는 핵심 공정입니다. 투입 순서와 정밀 계량은 품질의 기본입니다.
A6: ■ 원재료 투입 프로세스 (Sequence of Addition)
A8: 분산 효율 극대화 및 미세 기포 방지를 위해 반드시 아래 순서를 엄수합니다.
A10: 1단계: 메인 액상 및 저수축제 혼합 (Base Liquids)
A11: 가장 양이 많고 기초가 되는 액체들을 먼저 섞습니다.
A12: 투입 원료: 불포화수지 + 저수축제 + SM(희석제)
A14: 2단계: 희석제, 첨가제 및 중합방지제 투입 (Additives)
A15: 수지의 안정성과 분산력을 높이는 성분들을 넣습니다.
A16: 투입 원료: SM(희석제) + K996(분산제) + K972(분리방지제) + CBA109N(중합방지제)
A18: 3단계: 경화제 투입 (Initiator)
A19: 투입 원료: T-BPB(경화제)
... A90: 말기점도검사 : 설계 점도에 따른 숙성 점도 확인 데이터 화 합니다.

Sheet SMC시트관리가이드
B2: SMC 시트 관리 핵심 수칙 | L2: Quy tắc cốt lõi về quản lý tấm SMC
B4: 1. 온도 관리 | L4: 1. Quản lý nhiệt độ
B6: 적정 온도: 반드시 20±5°C의 서늘한 곳에 보관해야 합니다. | L6: Nhiệt độ thích hợp: Phải bảo quản ở nơi thoáng mát với nhiệt độ duy trì ở mức 20±5°C.
B7: 주의사항: 30°C 이상의 고온에 장시간 노출되면 성형하기도 전에 딱딱하게 굳는 조기 경화(Pre-gelation)
B8: 현상이 발생하면 불량의 원인이 됩니다. | L8: Lưu ý: Nếu tiếp xúc với nhiệt độ cao trên 30°C trong thời gian dài, hiện tượng
L9: đông kết sớm (Pre-gelation) sẽ xảy ra khiến tấm bị cứng lại trước khi tạo hình, dẫn
B10: 2. 밀봉 및 습기 차단 | L10: đến sản phẩm lỗi.
B12: 밀봉 유지: 습기가 스며들면 성형 시 기포(Blister)가 발생하므로 사용하고 남은 시트는 반드시 알루미늄 | L12: 2. Niêm phong và ngăn chặn độ ẩm
B13: 증착 필름 등으로 공기가 통하지 않게 밀봉하여야 합니다.
L14: Duy trì niêm phong: Nếu độ ẩm xâm nhập, các bọt khí (Blister) sẽ xuất hiện trong quá
B15: 3. 숙성(Maturation) 기간 준수 | L15: trình tạo hình. Do đó, các tấm còn dư sau khi sử dụng phải được niêm phong kín bằng
B16: 적정 점도 확보: 증점제(MgO 등)가 충분히 반응하여 금형 내에서 잘 흐를 수 있는 점도가 될 때까지 | L16: màng nhôm chuyên dụng để ngăn không khí lọt vào.
B17: 보통 18~36시간 정도의 숙성 기간을 거친 후 투입하세요.
B18: 과숙성 주의: 너무 오래 방치(보통 2~3개월 이상)하면 유동성이 떨어져 미충진 불량이 생길 수 있습니다. | L18: 3. Tuân thủ thời gian ủ (Maturation)
B20: 4. 선입선출 (FIFO) 원칙 | L20: Đảm bảo độ nhớt phù hợp: Để chất làm đặc (như MgO) phản ứng đầy đủ và đạt đến độ
B21: 제조일 확인: 먼저 들어온 시트를 먼저 사용하는 선입선출을 철저히 지켜야 합니다. 장기 보관된 시트는 | L21: nhớt có thể chảy tốt trong khuôn, hãy đưa vào sử dụng sau thời gian ủ thông thường
B22: 성형성이 급격히 저하됩니다. | L22: từ 18 đến 36 giờ.
B24: 5. 작업 전 예열 (Winter Season) | L24: Cảnh báo quá hạn: Nếu để quá lâu (thường trên 2~3 tháng), tính lưu động sẽ giảm, dẫn
L25: đến lỗi không điền đầy khuôn.
B26: 상온 적응: 작업 전 약 12~24시간 정도 미리 작업장 온도로 옮겨두어 시트의 온도를 안정시킨 후 성형하는
B27: 것이 좋습니다. | L27: 4. Nguyên tắc nhập trước xuất trước (FIFO)
L29: Kiểm tra ngày sản xuất: Phải tuân thủ nghiêm ngặt nguyên tắc FIFO, sử dụng những tấm
L30: nhập kho trước. Những tấm bảo quản quá lâu sẽ bị giảm mạnh khả năng tạo hình.
L32: 5. Làm ấm trước khi làm việc (Mùa đông)
L34: Thích nghi với nhiệt độ phòng: Trước khi làm việc khoảng 12~24 giờ, nên chuyển tấm
L35: SMC đến khu vực làm việc để ổn định nhiệt độ trước khi tiến hành tạo hình.

Sheet SMC_Calculation (TEST)
B2: SMC MACHINE SETTING PROGRAM(IDEAL) | M2: Raw material for SMC Production(MANHOLE C250) | U2: =P5+P6 -> 550
S3: SMC | T3: SMC | X3: 0.5
M4: ITEM | N4: PART NAME | O4: Density (g/cm3) | P4: Parts Wt(KG) | Q4: WT % | R4: Volume(Liters) | S4: Vol % | T4: Vol % | U4: PHR | X4: 950
C5: Main Machine Belt Speed | F5: 10 | H5: M/Min | M5: Resin | N5: VUP-6737 | O5: 1.1 | P5: 385 | Q5: =P5/$P$21 -> 0.141682 | R5: =P5/O5 -> 350 | S5: =R5/$R$20 -> 0.33118597 | T5: =R5/$R$21 -> 0.25015157 | U5: =P5/$U$2*100 -> 70
M6: LPA | N6: JP-30 LPA | O6: 1 | P6: 165 | Q6: =P6/$P$21 -> 0.060720857 | R6: =P6/O6 -> 165 | S6: =R6/$R$20 -> 0.15613053 | T6: =R6/$R$21 -> 0.1179286 | U6: =P6/$U$2*100 -> 30 | Y6: =3.14*X3*X4/60 -> 24.858333
B7: Basic parametor setting | M7: STYRENE MONOMER | N7: SM | O7: 0.906 | P7: 36 | Q7: =P7/$P$21 -> 0.013248187 | R7: =P7/O7 -> 39.735099 | S7: =R7/$R$20 -> 0.037599164 | T7: =R7/$R$21 -> 0.028399421 | U7: =P7/$U$2*100 -> 6.5454545
C8: SMC Paste Matric Specific Gravity | F8: =O20 -> 1.7484727 | G8: Kg/M3 | M8: Tbpb (T-Butyle Perbenzoate) | N8: TBPB | O8: 1.04 | P8: 8.3 | Q8: =P8/$P$21 -> 0.0030544431 | R8: =P8/O8 -> 7.9807692 | S8: =R8/$R$20 -> 0.007551768 | T8: =R8/$R$21 -> 0.0057040056 | U8: =P8/$U$2*100 -> 1.5090909
C9: SMC Carrier film(thickness) | F9: 0.04 | G9: mm | M9: Zinc stearate | N9: HI-FLOW-GP(Zn-ST) | O9: 1.095 | P9: 28 | Q9: =P9/$P$21 -> 0.010304145 | R9: =P9/O9 -> 25.570776 | S9: =R9/$R$20 -> 0.024196235 | T9: =R9/$R$21 -> 0.018275914 | U9: =P9/$U$2*100 -> 5.0909091
C10: SMC width | F10: 930 | G10: mm | M10: Color pigment | N10: HW-Gray | O10: 2.05 | P10: 50 | Q10: =P10/$P$21 -> 0.01840026 | R10: =P10/O10 -> 24.390244 | S10: =R10/$R$20 -> 0.023079162 | T10: =R10/$R$21 -> 0.017432165 | U10: =P10/$U$2*100 -> 9.0909091
M11: rheology modifier | N11: CBA-308 | O11: 1.2 | Q11: =P11/$P$21 -> 0 | R11: =P11/O11 -> 0 | S11: =R11/$R$20 -> 0 | T11: =R11/$R$21 -> 0 | U11: =P11/$U$2*100 -> 0
C12: SMC UNIT WEIGHT | F12: 4740 | G12: g/M2 | M12: PE POWDER | N12: FHP05040 | O12: 0.958 | Q12: =P12/$P$21 -> 0 | R12: =P12/O12 -> 0 | S12: =R12/$R$20 -> 0 | T12: =R12/$R$21 -> 0 | U12: =P12/$U$2*100 -> 0
C13: GLASS CONTENTS | F13: 0.32 | M13: PBQ(Inhibitor) | N13: CBA-109N | O13: 1.2 | P13: 1.7 | Q13: =P13/$P$21 -> 0.00062560883 | R13: =P13/O13 -> 1.4166667 | S13: =R13/$R$20 -> 0.0013405146 | T13: =R13/$R$21 -> 0.0010125183 | U13: =P13/$U$2*100 -> 0.30909091
F14: =F12*F13 -> 1516.8 | G14: g/M2 | M14: Dispersing Agent | N14: BYK W972 | O14: 1.015 | P14: 2.2 | Q14: =P14/$P$21 -> 0.00080961143 | R14: =P14/O14 -> 2.1674877 | S14: =R14/$R$20 -> 0.0020509757 | T14: =R14/$R$21 -> 0.0015491441 | U14: =P14/$U$2*100 -> 0.4
C15: SMC Paste weight without Glass | F15: =F12-F14 -> 3223.2 | G15: g/M2 | M15: Wetting & Dispersing Agent | N15: BYK W996 | O15: 1.035 | Q15: =P15/$P$21 -> 0 | R15: =P15/O15 -> 0 | S15: =R15/$R$20 -> 0 | T15: =R15/$R$21 -> 0 | U15: =P15/$U$2*100 -> 0
M16: Caco3 | N16: Calcum carbonate | O16: 2.7 | P16: 1155 | Q16: =P16/$P$21 -> 0.425046 | R16: =P16/O16 -> 427.77778 | S16: =R16/$R$20 -> 0.40478285 | T16: =R16/$R$21 -> 0.30574081 | U16: =P16/$U$2*100 -> 210
C17: 1st Doctor Blade Height(Lower) | F17: ON | G17: =IF(F17="ON",1,0) -> 1 | M17: MgO Paste | N17: CBU-613 | O17: 1.3 | P17: =P8*2 -> 16.6 | Q17: =P17/$P$21 -> 0.0061088862 | R17: =P17/O17 -> 12.769231 | S17: =R17/$R$20 -> 0.012082829 | T17: =R17/$R$21 -> 0.0091264089 | U17: =P17/$U$2*100 -> 3.0181818
C18: 2nd Doctor Blade Height(Upper) | F18: ON | G18: =IF(F18="ON",1,0) -> 1 | M18: Glass | N18: JUSHI 442K | O18: 2.54 | P18: =S26 -> 869.55294 | Q18: =P18/$P$21 -> 0.32 | R18: =P18/O18 -> 342.34368 | T18: =R18/$R$21 -> 0.24467945 | U18: =P18/$U$2*100 -> 158.10053
C20: SMC WEIGHT Based on Width | F20: =F12*1*(F10/1000) -> 4408.2 | G20: g/ (1M x | H20: =F10/1000 -> 0.93 | I20: M) | M20: MATRICS Total | O20: =O5*S5+O6*S6+O7*S7+O8*S8+O9*S9+O10*S10+O11*S11+O12*S12+O13*S13+O14*S14+O15*S15+O16*S16+O17*S17 -> 1.7484727 | P20: =SUM(P5:P17) -> 1847.8 | Q20: =P20/$P$21 -> 0.68 | R20: =SUM(R5:R17) -> 1056.8081 | S20: =R20/$R$20 -> 1 | U20: =P20/$U$2*100 -> 335.96364
M21: SMC Total | O21: =O5*T5+O6*T6+O7*T7+O8*T8+O9*T9+O10*T10+O11*T11+O12*T12+O13*T13+O14*T14+O15*T15+O16*T16+O17*T17+O18*T18 -> 1.9421431 | P21: =SUM(P5:P18) -> 2717.3529 | Q21: =P21/$P$21 -> 1 | R21: =SUM(R5:R18) -> 1399.1517 | T21: =SUM(T5:T18) -> 1 | U21: =SUM(U5:U18) -> 494.06417
C22: GLASS Weight | F22: =F20*F13 -> 1410.624 | G22: g/SMC Width
C23: SMC Paste weight without Glass | F23: =F20-F22 -> 2997.576 | G23: g/SMC Width
C25: 200x200mm SMC WT | F25: =F12/25 -> 189.6 | G25: g | Q25: Matrix | R25: =100%-R26 -> 0.68 | S25: =P20 -> 1847.8
C26: 200x200mm GLASS WT | F26: =F25*F13 -> 60.672 | G26: g | Q26: Glass | R26: =F13 -> 0.32 | S26: =S25*R26/R25 -> 869.55294
C27: 200x200mm PASTE WT | F27: =F25-F26 -> 128.928 | G27: g
B29: 1st Glass Cutter | F29: ON | G29: =IF(F29="ON",1,0) -> 1
C30: 1st Glass Tex | D30: 4800 | E30: TEX | F30: =D30 -> 4800 | G30: g | H30: / | I30: =1000*100*10 -> 1000000 | J30: mm
C31: 1st Cutted glass size | D31: 1 | E31: (inch) | F31: =F30*I31/I30 -> 0.12192 | G31: g | H31: / | I31: =25.4*D31 -> 25.4 | J31: mm
C32: Nos of Suppying Glass Rovings(1st Cutter) : | F32: 24 | G32: (Default : 32)
C33: Nos of roving cutter(1st) : | F33: 19 | G33: (Default : 24)
B34: 2nd Glass Cutter | F34: ON | G34: =IF(F34="ON",1,0) -> 1
C35: 2nd Glass Tex | D35: 2400 | E35: TEX | F35: =D35 -> 2400 | G35: g | H35: / | I35: =1000*100*10 -> 1000000 | J35: mm
C36: 2nd Cutted glass size | D36: 1 | E36: (inch) | F36: =F35*I36/I35 -> 0.06096 | G36: g | H36: / | I36: =25.4*D36 -> 25.4 | J36: mm
C37: Nos of Suppying Glass Rovings(2nd Cutter) : | F37: 36 | G37: (Default : 32)
C38: Nos of roving cutter : | F38: 20 | G38: (Default : 24)
B39: 3rd Direct Roving | F39: OFF | G39: =IF(F39="ON",1,0) -> 0
C40: 3nd Glass Tex | D40: 4800 | E40: TEX | F40: =D40 -> 4800 | G40: g | H40: / | I40: =1000*100*10 -> 1000000 | J40: mm
C41: Nos of Direct roving | D41: 48 | E41: (PCS) | F41: =F40*I41/I40 -> 4.8 | G41: g | H41: / | I41: =1000 -> 1000 | J41: mm
B43: 4th Woven Roving | F43: OFF | G43: =IF(F43="ON",1,0) -> 0
C44: 4th Woven Roving | D44: 580 | E44: g/M2 | F44: =D44 -> 580 | G44: g | H44: / | I44: =1000 -> 1000 | J44: mm
C47: 1. Glass weight for 1st cutter | F47: =IF(G29=0,0,IF(G34=1,(F22-F49-F50)/2,(F22-F49-F50))) -> 705.312 | G47: g | H47: / | I47: M | J47: =F47/F20 -> 0.16
...
